Workbook

Sheet README
A1: GNC Intern Evaluation Matrix
A3: Purpose
A4: Rank ~30 GNC intern candidates by weighted fit score across 13 criteria.
A6: How to use
A7: 1. Open the 'Scoring' sheet — enter one candidate per row.
A8: 2. YELLOW cells = your inputs. GREEN cells = auto-computed.
A9: 3. Score most criteria on a 1–5 scale. See 'Rubric' sheet for what each score means.
A10: 4. University name auto-maps to a tier via 'Uni_Tiers' (edit that sheet to add/move unis).
A11: 5. Department auto-maps to fit score via 'Dept_Fit' (editable).
A12: 6. GPA, academic status, Teknofest level all auto-convert to 1–5 scores.
A13: 7. Tech interview = average of 5 subscores (Controls, Math, Coding, Debugging, Communication).
A14: 8. Set 'Disqualified?' = Y to exclude a candidate from ranking (score still shown).
... A26: 20 (all 1s) to 100 (all 5s). A candidate scoring 75+ is generally a strong hire.

Sheet Scoring
A1: Identity | C1: Background (auto) | H1: Experience (1-5) | O1: Tech Interview (1-5) | T1: Result | X1: Auto-Computed Component Scores
A2: # | B2: Name | C2: University | D2: Department | E2: Academic Status | F2: GPA (0-4) | G2: Teknofest | H2: Real Project (1-5) | I2: Portfolio (1-5) | J2: Coursework (1-5) | K2: Tools (1-5) | L2: RC/UAV (1-5) | M2: English (1-5) | N2: HR Feedback (1-5) | O2: Controls/GNC | P2: Math/Physics | Q2: Coding | R2: Debugging | S2: Communication | T2: Disqualified? | U2: Weighted Score | V2: Rank | W2: Notes | X2: UniTier Score | Y2: Dept Score | Z2: GPA Score | AA2: Status Score | AB2: Teknofest Score | AC2: Tech Composite | AD2: DQ Row Pos
A3: 1 | B3: Abdellah Bougataya | C3: Yıldız Teknik | D3: Control Engineering | E3: 3rd year | F3: 3.34 | G3: None | H3: 4 | I3: 2 | J3: 4 | K3: 5 | L3: 3 | M3: 5 | T3: N | U3: =IF(B3="","",(X3*Weights!$B$2+Y3*Weights!$B$3+Z3*Weights!$B$4+AA3*Weights!$B$5+AB3*Weights!$B$6+H3*Weights!$B$7+I3*Weights!$B$8+J3*Weights!$B$9+K3*Weights!$B$10+L3*Weights!$B$11+M3*Weights!$B$12+N3*Weights!$B$13+AC3*Weights!$B$14)/5) | V3: =IF(OR(B3="",T3="Y"),"",1+SUMPRODUCT(((U$3:U$32>U3)+((U$3:U$32=U3)*(ROW(U$3:U$32)<3)))*(T$3:T$32<>"Y")*(B$3:B$32<>""))) | W3: Strong all-round; ArduPilot SITL + Gazebo + bare-metal firmware; AVIONX team (custom FC). No Teknofest involvement stated. | X3: =IFERROR(VLOOKUP(VLOOKUP(C3,Uni_Tiers!$A$2:$B$24,2,FALSE()),Uni_Tiers!$E$2:$F$6,2,FALSE()),IF(C3="",1,2)) | Y3: =IFERROR(VLOOKUP(D3,Dept_Fit!$A$2:$B$15,2,FALSE()),1) | Z3: =IF(F3="",1,IF(F3>=3.5,5,IF(F3>=3,4,IF(F3>=2.5,3,IF(F3>=2,2,1))))) | AA3: =IFERROR(VLOOKUP(E3,Status_Map!$A$2:$B$9,2,FALSE()),1) | AB3: =IFERROR(VLOOKUP(G3,Teknofest_Map!$A$2:$B$6,2,FALSE()),1) | AC3: =IFERROR(AVERAGE(O3,P3,Q3,R3,S3),0) | AD3: =IF(T3="Y",ROW()-2,"")
A4: 2 | B4: Abdurakhmon Sobitkhanov | C4: Yıldız Teknik | D4: Control Engineering | E4: 3rd year | F4: 3.53 | G4: None | H4: 4 | I4: 2 | J4: 2 | K4: 4 | L4: 4 | M4: 3 | T4: N | U4: =IF(B4="","",(X4*Weights!$B$2+Y4*Weights!$B$3+Z4*Weights!$B$4+AA4*Weights!$B$5+AB4*Weights!$B$6+H4*Weights!$B$7+I4*Weights!$B$8+J4*Weights!$B$9+K4*Weights!$B$10+L4*Weights!$B$11+M4*Weights!$B$12+N4*Weights!$B$13+AC4*Weights!$B$14)/5) | V4: =IF(OR(B4="",T4="Y"),"",1+SUMPRODUCT(((U$3:U$32>U4)+((U$3:U$32=U4)*(ROW(U$3:U$32)<4)))*(T$3:T$32<>"Y")*(B$3:B$32<>""))) | W4: YTU Kontrol ve Otomasyon Müh, AGNO 3.53. Inner-loop PID + IMU; Simulink modeling. | X4: =IFERROR(VLOOKUP(VLOOKUP(C4,Uni_Tiers!$A$2:$B$24,2,FALSE()),Uni_Tiers!$E$2:$F$6,2,FALSE()),IF(C4="",1,2)) | Y4: =IFERROR(VLOOKUP(D4,Dept_Fit!$A$2:$B$15,2,FALSE()),1) | Z4: =IF(F4="",1,IF(F4>=3.5,5,IF(F4>=3,4,IF(F4>=2.5,3,IF(F4>=2,2,1))))) | AA4: =IFERROR(VLOOKUP(E4,Status_Map!$A$2:$B$9,2,FALSE()),1) | AB4: =IFERROR(VLOOKUP(G4,Teknofest_Map!$A$2:$B$6,2,FALSE()),1) | AC4: =IFERROR(AVERAGE(O4,P4,Q4,R4,S4),0) | AD4: =IF(T4="Y",ROW()-2,"")
A5: 3 | B5: Ahmet Buğra Kallat | C5: ITU | D5: Mechanical Engineering | E5: 4th year | G5: Podium / finals | H5: 4 | I5: 3 | J5: 4 | K5: 5 | L5: 4 | M5: 4 | T5: N | U5: =IF(B5="","",(X5*Weights!$B$2+Y5*Weights!$B$3+Z5*Weights!$B$4+AA5*Weights!$B$5+AB5*Weights!$B$6+H5*Weights!$B$7+I5*Weights!$B$8+J5*Weights!$B$9+K5*Weights!$B$10+L5*Weights!$B$11+M5*Weights!$B$12+N5*Weights!$B$13+AC5*Weights!$B$14)/5) | V5: =IF(OR(B5="",T5="Y"),"",1+SUMPRODUCT(((U$3:U$32>U5)+((U$3:U$32=U5)*(ROW(U$3:U$32)<5)))*(T$3:T$32<>"Y")*(B$3:B$32<>""))) | W5: İTÜ Makine Müh; Teknofest Savaşan İHA 'En İyi Tasarım' + Serbest Görev İHA 3.lük; IMechE UAS Challenge finalist; avionics, autonomous systems, UAV design + control. | X5: =IFERROR(VLOOKUP(VLOOKUP(C5,Uni_Tiers!$A$2:$B$24,2,FALSE()),Uni_Tiers!$E$2:$F$6,2,FALSE()),IF(C5="",1,2)) | Y5: =IFERROR(VLOOKUP(D5,Dept_Fit!$A$2:$B$15,2,FALSE()),1) | Z5: =IF(F5="",1,IF(F5>=3.5,5,IF(F5>=3,4,IF(F5>=2.5,3,IF(F5>=2,2,1))))) | AA5: =IFERROR(VLOOKUP(E5,Status_Map!$A$2:$B$9,2,FALSE()),1) | AB5: =IFERROR(VLOOKUP(G5,Teknofest_Map!$A$2:$B$6,2,FALSE()),1) | AC5: =IFERROR(AVERAGE(O5,P5,Q5,R5,S5),0) | AD5: =IF(T5="Y",ROW()-2,"")
A6: 4 | B6: Ali Assani | C6: Yıldız Teknik | D6: Control Engineering | E6: Fresh graduate (<1 yr) | G6: Applied only | H6: 5 | I6: 3 | J6: 5 | K6: 4 | L6: 5 | M6: 3 | T6: N | U6: =IF(B6="","",(X6*Weights!$B$2+Y6*Weights!$B$3+Z6*Weights!$B$4+AA6*Weights!$B$5+AB6*Weights!$B$6+H6*Weights!$B$7+I6*Weights!$B$8+J6*Weights!$B$9+K6*Weights!$B$10+L6*Weights!$B$11+M6*Weights!$B$12+N6*Weights!$B$13+AC6*Weights!$B$14)/5) | V6: =IF(OR(B6="",T6="Y"),"",1+SUMPRODUCT(((U$3:U$32>U6)+((U$3:U$32=U6)*(ROW(U$3:U$32)<6)))*(T$3:T$32<>"Y")*(B$3:B$32<>""))) | W6: YTU Control & Automation graduate; MATLAB Mini Drone Competition Stage 1; aircraft control + MATLAB/Simulink exposure. | X6: =IFERROR(VLOOKUP(VLOOKUP(C6,Uni_Tiers!$A$2:$B$24,2,FALSE()),Uni_Tiers!$E$2:$F$6,2,FALSE()),IF(C6="",1,2)) | Y6: =IFERROR(VLOOKUP(D6,Dept_Fit!$A$2:$B$15,2,FALSE()),1) | Z6: =IF(F6="",1,IF(F6>=3.5,5,IF(F6>=3,4,IF(F6>=2.5,3,IF(F6>=2,2,1))))) | AA6: =IFERROR(VLOOKUP(E6,Status_Map!$A$2:$B$9,2,FALSE()),1) | AB6: =IFERROR(VLOOKUP(G6,Teknofest_Map!$A$2:$B$6,2,FALSE()),1) | AC6: =IFERROR(AVERAGE(O6,P6,Q6,R6,S6),0) | AD6: =IF(T6="Y",ROW()-2,"")
A7: 5 | B7: Barış Ağacık | C7: Yıldız Teknik | D7: Control Engineering | E7: 4th year | F7: 3.03 | G7: None | H7: 5 | I7: 2 | J7: 4 | K7: 5 | L7: 2 | M7: 4 | T7: N | U7: =IF(B7="","",(X7*Weights!$B$2+Y7*Weights!$B$3+Z7*Weights!$B$4+AA7*Weights!$B$5+AB7*Weights!$B$6+H7*Weights!$B$7+I7*Weights!$B$8+J7*Weights!$B$9+K7*Weights!$B$10+L7*Weights!$B$11+M7*Weights!$B$12+N7*Weights!$B$13+AC7*Weights!$B$14)/5) | V7: =IF(OR(B7="",T7="Y"),"",1+SUMPRODUCT(((U$3:U$32>U7)+((U$3:U$32=U7)*(ROW(U$3:U$32)<7)))*(T$3:T$32<>"Y")*(B$3:B$32<>""))) | W7: YTU Kontrol ve Otomasyon Müh (Lisans) 2022-2026, AGNO 3.03. MSC Nastran/Patran (software, not MSc). | X7: =IFERROR(VLOOKUP(VLOOKUP(C7,Uni_Tiers!$A$2:$B$24,2,FALSE()),Uni_Tiers!$E$2:$F$6,2,FALSE()),IF(C7="",1,2)) | Y7: =IFERROR(VLOOKUP(D7,Dept_Fit!$A$2:$B$15,2,FALSE()),1) | Z7: =IF(F7="",1,IF(F7>=3.5,5,IF(F7>=3,4,IF(F7>=2.5,3,IF(F7>=2,2,1))))) | AA7: =IFERROR(VLOOKUP(E7,Status_Map!$A$2:$B$9,2,FALSE()),1) | AB7: =IFERROR(VLOOKUP(G7,Teknofest_Map!$A$2:$B$6,2,FALSE()),1) | AC7: =IFERROR(AVERAGE(O7,P7,Q7,R7,S7),0) | AD7: =IF(T7="Y",ROW()-2,"")
A8: 6 | B8: Emirhan Oskay | C8: Yıldız Teknik | D8: Control Engineering | E8: MSc student | F8: 3.56 | G8: None | H8: 4 | I8: 2 | J8: 4 | K8: 5 | L8: 1 | M8: 3 | T8: N | U8: =IF(B8="","",(X8*Weights!$B$2+Y8*Weights!$B$3+Z8*Weights!$B$4+AA8*Weights!$B$5+AB8*Weights!$B$6+H8*Weights!$B$7+I8*Weights!$B$8+J8*Weights!$B$9+K8*Weights!$B$10+L8*Weights!$B$11+M8*Weights!$B$12+N8*Weights!$B$13+AC8*Weights!$B$14)/5) | V8: =IF(OR(B8="",T8="Y"),"",1+SUMPRODUCT(((U$3:U$32>U8)+((U$3:U$32=U8)*(ROW(U$3:U$32)<8)))*(T$3:T$32<>"Y")*(B$3:B$32<>""))) | W8: YTU. CV shows BSc AGNO 3.41 + ongoing MSc AGNO 3.56. 'Aday Mühendis' role at YTU; advisor at ITU. | X8: =IFERROR(VLOOKUP(VLOOKUP(C8,Uni_Tiers!$A$2:$B$24,2,FALSE()),Uni_Tiers!$E$2:$F$6,2,FALSE()),IF(C8="",1,2)) | Y8: =IFERROR(VLOOKUP(D8,Dept_Fit!$A$2:$B$15,2,FALSE()),1) | Z8: =IF(F8="",1,IF(F8>=3.5,5,IF(F8>=3,4,IF(F8>=2.5,3,IF(F8>=2,2,1))))) | AA8: =IFERROR(VLOOKUP(E8,Status_Map!$A$2:$B$9,2,FALSE()),1) | AB8: =IFERROR(VLOOKUP(G8,Teknofest_Map!$A$2:$B$6,2,FALSE()),1) | AC8: =IFERROR(AVERAGE(O8,P8,Q8,R8,S8),0) | AD8: =IF(T8="Y",ROW()-2,"")
A9: 7 | B9: Enes Göktuğ Güneş | C9: Other | D9: Software Engineering | E9: 3rd year | G9: None | H9: 4 | I9: 4 | J9: 1 | K9: 3 | L9: 4 | M9: 3 | T9: N | U9: =IF(B9="","",(X9*Weights!$B$2+Y9*Weights!$B$3+Z9*Weights!$B$4+AA9*Weights!$B$5+AB9*Weights!$B$6+H9*Weights!$B$7+I9*Weights!$B$8+J9*Weights!$B$9+K9*Weights!$B$10+L9*Weights!$B$11+M9*Weights!$B$12+N9*Weights!$B$13+AC9*Weights!$B$14)/5) | V9: =IF(OR(B9="",T9="Y"),"",1+SUMPRODUCT(((U$3:U$32>U9)+((U$3:U$32=U9)*(ROW(U$3:U$32)<9)))*(T$3:T$32<>"Y")*(B$3:B$32<>""))) | W9: Fatih Sultan Mehmet Foundation U, Software Eng, 3rd year. | X9: =IFERROR(VLOOKUP(VLOOKUP(C9,Uni_Tiers!$A$2:$B$24,2,FALSE()),Uni_Tiers!$E$2:$F$6,2,FALSE()),IF(C9="",1,2)) | Y9: =IFERROR(VLOOKUP(D9,Dept_Fit!$A$2:$B$15,2,FALSE()),1) | Z9: =IF(F9="",1,IF(F9>=3.5,5,IF(F9>=3,4,IF(F9>=2.5,3,IF(F9>=2,2,1))))) | AA9: =IFERROR(VLOOKUP(E9,Status_Map!$A$2:$B$9,2,FALSE()),1) | AB9: =IFERROR(VLOOKUP(G9,Teknofest_Map!$A$2:$B$6,2,FALSE()),1) | AC9: =IFERROR(AVERAGE(O9,P9,Q9,R9,S9),0) | AD9: =IF(T9="Y",ROW()-2,"")
A10: 8 | B10: Gonca Sude Şahbaz | C10: Eskişehir Osmangazi | D10: Electrical & Electronics Engineering | E10: MSc student | F10: 2.99 | G10: Participated multiple times | H10: 2 | I10: 4 | J10: 1 | K10: 4 | L10: 1 | M10: 4 | T10: N | U10: =IF(B10="","",(X10*Weights!$B$2+Y10*Weights!$B$3+Z10*Weights!$B$4+AA10*Weights!$B$5+AB10*Weights!$B$6+H10*Weights!$B$7+I10*Weights!$B$8+J10*Weights!$B$9+K10*Weights!$B$10+L10*Weights!$B$11+M10*Weights!$B$12+N10*Weights!$B$13+AC10*Weights!$B$14)/5) | V10: =IF(OR(B10="",T10="Y"),"",1+SUMPRODUCT(((U$3:U$32>U10)+((U$3:U$32=U10)*(ROW(U$3:U$32)<10)))*(T$3:T$32<>"Y")*(B$3:B$32<>""))) | W10: BSc EEE Eskişehir Osmangazi 2021-2025 (GPA 2.99), now pursuing Yüksek Lisans. Multiple Teknofest events. | X10: =IFERROR(VLOOKUP(VLOOKUP(C10,Uni_Tiers!$A$2:$B$24,2,FALSE()),Uni_Tiers!$E$2:$F$6,2,FALSE()),IF(C10="",1,2)) | Y10: =IFERROR(VLOOKUP(D10,Dept_Fit!$A$2:$B$15,2,FALSE()),1) | Z10: =IF(F10="",1,IF(F10>=3.5,5,IF(F10>=3,4,IF(F10>=2.5,3,IF(F10>=2,2,1))))) | AA10: =IFERROR(VLOOKUP(E10,Status_Map!$A$2:$B$9,2,FALSE()),1) | AB10: =IFERROR(VLOOKUP(G10,Teknofest_Map!$A$2:$B$6,2,FALSE()),1) | AC10: =IFERROR(AVERAGE(O10,P10,Q10,R10,S10),0) | AD10: =IF(T10="Y",ROW()-2,"")
A11: 9 | B11: Hacer Mehmet (Hajir Al-Nuaimi) | C11: Yıldız Teknik | D11: Control Engineering | E11: 4th year | G11: Participated once | H11: 5 | I11: 3 | J11: 5 | K11: 5 | L11: 4 | M11: 5 | T11: N | U11: =IF(B11="","",(X11*Weights!$B$2+Y11*Weights!$B$3+Z11*Weights!$B$4+AA11*Weights!$B$5+AB11*Weights!$B$6+H11*Weights!$B$7+I11*Weights!$B$8+J11*Weights!$B$9+K11*Weights!$B$10+L11*Weights!$B$11+M11*Weights!$B$12+N11*Weights!$B$13+AC11*Weights!$B$14)/5) | V11: =IF(OR(B11="",T11="Y"),"",1+SUMPRODUCT(((U$3:U$32>U11)+((U$3:U$32=U11)*(ROW(U$3:U$32)<11)))*(T$3:T$32<>"Y")*(B$3:B$32<>""))) | W11: YTU Control Eng senior, expected Dec 2026. Senior thesis: VTOL UAV design & flight control. MATLAB MiniDrone Competition 2024. | X11: =IFERROR(VLOOKUP(VLOOKUP(C11,Uni_Tiers!$A$2:$B$24,2,FALSE()),Uni_Tiers!$E$2:$F$6,2,FALSE()),IF(C11="",1,2)) | Y11: =IFERROR(VLOOKUP(D11,Dept_Fit!$A$2:$B$15,2,FALSE()),1) | Z11: =IF(F11="",1,IF(F11>=3.5,5,IF(F11>=3,4,IF(F11>=2.5,3,IF(F11>=2,2,1))))) | AA11: =IFERROR(VLOOKUP(E11,Status_Map!$A$2:$B$9,2,FALSE()),1) | AB11: =IFERROR(VLOOKUP(G11,Teknofest_Map!$A$2:$B$6,2,FALSE()),1) | AC11: =IFERROR(AVERAGE(O11,P11,Q11,R11,S11),0) | AD11: =IF(T11="Y",ROW()-2,"")
A12: 10 | B12: Hatixhe Merkaj | C12: ITU | D12: Electronics Engineering | E12: 3rd year | G12: None | H12: 3 | I12: 3 | J12: 1 | K12: 4 | L12: 4 | M12: 5 | T12: N | U12: =IF(B12="","",(X12*Weights!$B$2+Y12*Weights!$B$3+Z12*Weights!$B$4+AA12*Weights!$B$5+AB12*Weights!$B$6+H12*Weights!$B$7+I12*Weights!$B$8+J12*Weights!$B$9+K12*Weights!$B$10+L12*Weights!$B$11+M12*Weights!$B$12+N12*Weights!$B$13+AC12*Weights!$B$14)/5) | V12: =IF(OR(B12="",T12="Y"),"",1+SUMPRODUCT(((U$3:U$32>U12)+((U$3:U$32=U12)*(ROW(U$3:U$32)<12)))*(T$3:T$32<>"Y")*(B$3:B$32<>""))) | W12: ITU Electronics & Communication 3rd year. ITU Hyperbee team; MBSE work. | X12: =IFERROR(VLOOKUP(VLOOKUP(C12,Uni_Tiers!$A$2:$B$24,2,FALSE()),Uni_Tiers!$E$2:$F$6,2,FALSE()),IF(C12="",1,2)) | Y12: =IFERROR(VLOOKUP(D12,Dept_Fit!$A$2:$B$15,2,FALSE()),1) | Z12: =IF(F12="",1,IF(F12>=3.5,5,IF(F12>=3,4,IF(F12>=2.5,3,IF(F12>=2,2,1))))) | AA12: =IFERROR(VLOOKUP(E12,Status_Map!$A$2:$B$9,2,FALSE()),1) | AB12: =IFERROR(VLOOKUP(G12,Teknofest_Map!$A$2:$B$6,2,FALSE()),1) | AC12: =IFERROR(AVERAGE(O12,P12,Q12,R12,S12),0) | AD12: =IF(T12="Y",ROW()-2,"")
A13: 11 | B13: Hüseyin Kırca | C13: Other | D13: Mechatronics Engineering | E13: 3rd year | F13: 3.3 | G13: None | H13: 5 | I13: 3 | J13: 2 | K13: 5 | L13: 2 | M13: 3 | T13: N | U13: =IF(B13="","",(X13*Weights!$B$2+Y13*Weights!$B$3+Z13*Weights!$B$4+AA13*Weights!$B$5+AB13*Weights!$B$6+H13*Weights!$B$7+I13*Weights!$B$8+J13*Weights!$B$9+K13*Weights!$B$10+L13*Weights!$B$11+M13*Weights!$B$12+N13*Weights!$B$13+AC13*Weights!$B$14)/5) | V13: =IF(OR(B13="",T13="Y"),"",1+SUMPRODUCT(((U$3:U$32>U13)+((U$3:U$32=U13)*(ROW(U$3:U$32)<13)))*(T$3:T$32<>"Y")*(B$3:B$32<>""))) | W13: Kocaeli Üni Mekatronik 3. sınıf. Computer vision focus. No Teknofest mention. | X13: =IFERROR(VLOOKUP(VLOOKUP(C13,Uni_Tiers!$A$2:$B$24,2,FALSE()),Uni_Tiers!$E$2:$F$6,2,FALSE()),IF(C13="",1,2)) | Y13: =IFERROR(VLOOKUP(D13,Dept_Fit!$A$2:$B$15,2,FALSE()),1) | Z13: =IF(F13="",1,IF(F13>=3.5,5,IF(F13>=3,4,IF(F13>=2.5,3,IF(F13>=2,2,1))))) | AA13: =IFERROR(VLOOKUP(E13,Status_Map!$A$2:$B$9,2,FALSE()),1) | AB13: =IFERROR(VLOOKUP(G13,Teknofest_Map!$A$2:$B$6,2,FALSE()),1) | AC13: =IFERROR(AVERAGE(O13,P13,Q13,R13,S13),0) | AD13: =IF(T13="Y",ROW()-2,"")
A14: 12 | B14: Kübra Selin Yılmaz | C14: Yıldız Teknik | D14: Control Engineering | E14: 4th year | F14: 3.14 | G14: None | H14: 5 | I14: 5 | J14: 5 | K14: 5 | L14: 2 | M14: 3 | T14: N | U14: =IF(B14="","",(X14*Weights!$B$2+Y14*Weights!$B$3+Z14*Weights!$B$4+AA14*Weights!$B$5+AB14*Weights!$B$6+H14*Weights!$B$7+I14*Weights!$B$8+J14*Weights!$B$9+K14*Weights!$B$10+L14*Weights!$B$11+M14*Weights!$B$12+N14*Weights!$B$13+AC14*Weights!$B$14)/5) | V14: =IF(OR(B14="",T14="Y"),"",1+SUMPRODUCT(((U$3:U$32>U14)+((U$3:U$32=U14)*(ROW(U$3:U$32)<14)))*(T$3:T$32<>"Y")*(B$3:B$32<>""))) | W14: 4th year, AGNO 3.14. MSC Nastran/Patran (modal analysis) — software, not academic degree. | X14: =IFERROR(VLOOKUP(VLOOKUP(C14,Uni_Tiers!$A$2:$B$24,2,FALSE()),Uni_Tiers!$E$2:$F$6,2,FALSE()),IF(C14="",1,2)) | Y14: =IFERROR(VLOOKUP(D14,Dept_Fit!$A$2:$B$15,2,FALSE()),1) | Z14: =IF(F14="",1,IF(F14>=3.5,5,IF(F14>=3,4,IF(F14>=2.5,3,IF(F14>=2,2,1))))) | AA14: =IFERROR(VLOOKUP(E14,Status_Map!$A$2:$B$9,2,FALSE()),1) | AB14: =IFERROR(VLOOKUP(G14,Teknofest_Map!$A$2:$B$6,2,FALSE()),1) | AC14: =IFERROR(AVERAGE(O14,P14,Q14,R14,S14),0) | AD14: =IF(T14="Y",ROW()-2,"")
A15: 13 | B15: Mahmut Arpacı | C15: Other | D15: Mechatronics Engineering | E15: Fresh graduate (<1 yr) | F15: 3.03 | G15: Podium / finals | H15: 5 | I15: 4 | J15: 3 | K15: 4 | L15: 3 | M15: 3 | T15: N | U15: =IF(B15="","",(X15*Weights!$B$2+Y15*Weights!$B$3+Z15*Weights!$B$4+AA15*Weights!$B$5+AB15*Weights!$B$6+H15*Weights!$B$7+I15*Weights!$B$8+J15*Weights!$B$9+K15*Weights!$B$10+L15*Weights!$B$11+M15*Weights!$B$12+N15*Weights!$B$13+AC15*Weights!$B$14)/5) | V15: =IF(OR(B15="",T15="Y"),"",1+SUMPRODUCT(((U$3:U$32>U15)+((U$3:U$32=U15)*(ROW(U$3:U$32)<15)))*(T$3:T$32<>"Y")*(B$3:B$32<>""))) | W15: Marmara Üni Mekatronik, Gano 3.03. Teknofest 2025 Finalist – Hava Savunma Sistemleri + İnsansız Su Altı. | X15: =IFERROR(VLOOKUP(VLOOKUP(C15,Uni_Tiers!$A$2:$B$24,2,FALSE()),Uni_Tiers!$E$2:$F$6,2,FALSE()),IF(C15="",1,2)) | Y15: =IFERROR(VLOOKUP(D15,Dept_Fit!$A$2:$B$15,2,FALSE()),1) | Z15: =IF(F15="",1,IF(F15>=3.5,5,IF(F15>=3,4,IF(F15>=2.5,3,IF(F15>=2,2,1))))) | AA15: =IFERROR(VLOOKUP(E15,Status_Map!$A$2:$B$9,2,FALSE()),1) | AB15: =IFERROR(VLOOKUP(G15,Teknofest_Map!$A$2:$B$6,2,FALSE()),1) | AC15: =IFERROR(AVERAGE(O15,P15,Q15,R15,S15),0) | AD15: =IF(T15="Y",ROW()-2,"")
A16: 14 | B16: Melike Demirtaş | C16: Other | D16: Electronics Engineering | E16: 3rd year | F16: 2.94 | G16: Podium / finals | H16: 3 | I16: 2 | J16: 1 | K16: 4 | L16: 4 | M16: 3 | T16: N | U16: =IF(B16="","",(X16*Weights!$B$2+Y16*Weights!$B$3+Z16*Weights!$B$4+AA16*Weights!$B$5+AB16*Weights!$B$6+H16*Weights!$B$7+I16*Weights!$B$8+J16*Weights!$B$9+K16*Weights!$B$10+L16*Weights!$B$11+M16*Weights!$B$12+N16*Weights!$B$13+AC16*Weights!$B$14)/5) | V16: =IF(OR(B16="",T16="Y"),"",1+SUMPRODUCT(((U$3:U$32>U16)+((U$3:U$32=U16)*(ROW(U$3:U$32)<16)))*(T$3:T$32<>"Y")*(B$3:B$32<>""))) | W16: GTU EE 3rd year, GNO 2.94. Teknofest Savaşan İHA Aviyonik Lider 2025; 2024 Uluslararası İHA Türkiye Finalist. Portfolio is image-only PDF — review separately. | X16: =IFERROR(VLOOKUP(VLOOKUP(C16,Uni_Tiers!$A$2:$B$24,2,FALSE()),Uni_Tiers!$E$2:$F$6,2,FALSE()),IF(C16="",1,2)) | Y16: =IFERROR(VLOOKUP(D16,Dept_Fit!$A$2:$B$15,2,FALSE()),1) | Z16: =IF(F16="",1,IF(F16>=3.5,5,IF(F16>=3,4,IF(F16>=2.5,3,IF(F16>=2,2,1))))) | AA16: =IFERROR(VLOOKUP(E16,Status_Map!$A$2:$B$9,2,FALSE()),1) | AB16: =IFERROR(VLOOKUP(G16,Teknofest_Map!$A$2:$B$6,2,FALSE()),1) | AC16: =IFERROR(AVERAGE(O16,P16,Q16,R16,S16),0) | AD16: =IF(T16="Y",ROW()-2,"")
A17: 15 | B17: Momen Aref | C17: Yıldız Teknik | D17: Control Engineering | E17: Fresh graduate (<1 yr) | G17: Participated once | H17: 4 | I17: 2 | J17: 2 | K17: 4 | L17: 2 | M17: 5 | T17: N | U17: =IF(B17="","",(X17*Weights!$B$2+Y17*Weights!$B$3+Z17*Weights!$B$4+AA17*Weights!$B$5+AB17*Weights!$B$6+H17*Weights!$B$7+I17*Weights!$B$8+J17*Weights!$B$9+K17*Weights!$B$10+L17*Weights!$B$11+M17*Weights!$B$12+N17*Weights!$B$13+AC17*Weights!$B$14)/5) | V17: =IF(OR(B17="",T17="Y"),"",1+SUMPRODUCT(((U$3:U$32>U17)+((U$3:U$32=U17)*(ROW(U$3:U$32)<17)))*(T$3:T$32<>"Y")*(B$3:B$32<>""))) | W17: Yildiz Technical, Control & Automation 2021-2026. MPC/PID, embedded control. | X17: =IFERROR(VLOOKUP(VLOOKUP(C17,Uni_Tiers!$A$2:$B$24,2,FALSE()),Uni_Tiers!$E$2:$F$6,2,FALSE()),IF(C17="",1,2)) | Y17: =IFERROR(VLOOKUP(D17,Dept_Fit!$A$2:$B$15,2,FALSE()),1) | Z17: =IF(F17="",1,IF(F17>=3.5,5,IF(F17>=3,4,IF(F17>=2.5,3,IF(F17>=2,2,1))))) | AA17: =IFERROR(VLOOKUP(E17,Status_Map!$A$2:$B$9,2,FALSE()),1) | AB17: =IFERROR(VLOOKUP(G17,Teknofest_Map!$A$2:$B$6,2,FALSE()),1) | AC17: =IFERROR(AVERAGE(O17,P17,Q17,R17,S17),0) | AD17: =IF(T17="Y",ROW()-2,"")
A18: 16 | B18: Mostafa Mahmoud | C18: Yıldız Teknik | D18: Mechatronics Engineering | E18: 3rd year | F18: 3.35 | G18: Participated multiple times | H18: 4 | I18: 3 | J18: 3 | K18: 5 | L18: 4 | M18: 3 | T18: N | U18: =IF(B18="","",(X18*Weights!$B$2+Y18*Weights!$B$3+Z18*Weights!$B$4+AA18*Weights!$B$5+AB18*Weights!$B$6+H18*Weights!$B$7+I18*Weights!$B$8+J18*Weights!$B$9+K18*Weights!$B$10+L18*Weights!$B$11+M18*Weights!$B$12+N18*Weights!$B$13+AC18*Weights!$B$14)/5) | V18: =IF(OR(B18="",T18="Y"),"",1+SUMPRODUCT(((U$3:U$32>U18)+((U$3:U$32=U18)*(ROW(U$3:U$32)<18)))*(T$3:T$32<>"Y")*(B$3:B$32<>""))) | W18: YTU Mechatronics 3rd year, GPA 3.35. Teknofest Air Defence + AI in Aviation competitions. Embedded systems focus, M2lab candidate. | X18: =IFERROR(VLOOKUP(VLOOKUP(C18,Uni_Tiers!$A$2:$B$24,2,FALSE()),Uni_Tiers!$E$2:$F$6,2,FALSE()),IF(C18="",1,2)) | Y18: =IFERROR(VLOOKUP(D18,Dept_Fit!$A$2:$B$15,2,FALSE()),1) | Z18: =IF(F18="",1,IF(F18>=3.5,5,IF(F18>=3,4,IF(F18>=2.5,3,IF(F18>=2,2,1))))) | AA18: =IFERROR(VLOOKUP(E18,Status_Map!$A$2:$B$9,2,FALSE()),1) | AB18: =IFERROR(VLOOKUP(G18,Teknofest_Map!$A$2:$B$6,2,FALSE()),1) | AC18: =IFERROR(AVERAGE(O18,P18,Q18,R18,S18),0) | AD18: =IF(T18="Y",ROW()-2,"")
A19: 17 | B19: Muhammed Eyüp Rüzgar | C19: Yıldız Teknik | D19: Control Engineering | E19: 4th year | F19: 2.64 | G19: None | H19: 2 | I19: 2 | J19: 1 | K19: 4 | L19: 1 | M19: 3 | T19: N | U19: =IF(B19="","",(X19*Weights!$B$2+Y19*Weights!$B$3+Z19*Weights!$B$4+AA19*Weights!$B$5+AB19*Weights!$B$6+H19*Weights!$B$7+I19*Weights!$B$8+J19*Weights!$B$9+K19*Weights!$B$10+L19*Weights!$B$11+M19*Weights!$B$12+N19*Weights!$B$13+AC19*Weights!$B$14)/5) | V19: =IF(OR(B19="",T19="Y"),"",1+SUMPRODUCT(((U$3:U$32>U19)+((U$3:U$32=U19)*(ROW(U$3:U$32)<19)))*(T$3:T$32<>"Y")*(B$3:B$32<>""))) | W19: YTU Kontrol & Otomasyon, GNO 2.64, started Oct 2021. Robot programming, PLC, HMI. No Teknofest involvement. | X19: =IFERROR(VLOOKUP(VLOOKUP(C19,Uni_Tiers!$A$2:$B$24,2,FALSE()),Uni_Tiers!$E$2:$F$6,2,FALSE()),IF(C19="",1,2)) | Y19: =IFERROR(VLOOKUP(D19,Dept_Fit!$A$2:$B$15,2,FALSE()),1) | Z19: =IF(F19="",1,IF(F19>=3.5,5,IF(F19>=3,4,IF(F19>=2.5,3,IF(F19>=2,2,1))))) | AA19: =IFERROR(VLOOKUP(E19,Status_Map!$A$2:$B$9,2,FALSE()),1) | AB19: =IFERROR(VLOOKUP(G19,Teknofest_Map!$A$2:$B$6,2,FALSE()),1) | AC19: =IFERROR(AVERAGE(O19,P19,Q19,R19,S19),0) | AD19: =IF(T19="Y",ROW()-2,"")
A20: 18 | B20: Muhammed Kadir Aksoy | C20: Yıldız Teknik | D20: Control Engineering | E20: 4th year | G20: None | H20: 5 | I20: 5 | J20: 4 | K20: 5 | L20: 4 | M20: 3 | T20: N | U20: =IF(B20="","",(X20*Weights!$B$2+Y20*Weights!$B$3+Z20*Weights!$B$4+AA20*Weights!$B$5+AB20*Weights!$B$6+H20*Weights!$B$7+I20*Weights!$B$8+J20*Weights!$B$9+K20*Weights!$B$10+L20*Weights!$B$11+M20*Weights!$B$12+N20*Weights!$B$13+AC20*Weights!$B$14)/5) | V20: =IF(OR(B20="",T20="Y"),"",1+SUMPRODUCT(((U$3:U$32>U20)+((U$3:U$32=U20)*(ROW(U$3:U$32)<20)))*(T$3:T$32<>"Y")*(B$3:B$32<>""))) | W20: YTU Kontrol ve Otomasyon, son sınıf. YOLO26x-OBB benchmark work in portfolio. | X20: =IFERROR(VLOOKUP(VLOOKUP(C20,Uni_Tiers!$A$2:$B$24,2,FALSE()),Uni_Tiers!$E$2:$F$6,2,FALSE()),IF(C20="",1,2)) | Y20: =IFERROR(VLOOKUP(D20,Dept_Fit!$A$2:$B$15,2,FALSE()),1) | Z20: =IF(F20="",1,IF(F20>=3.5,5,IF(F20>=3,4,IF(F20>=2.5,3,IF(F20>=2,2,1))))) | AA20: =IFERROR(VLOOKUP(E20,Status_Map!$A$2:$B$9,2,FALSE()),1) | AB20: =IFERROR(VLOOKUP(G20,Teknofest_Map!$A$2:$B$6,2,FALSE()),1) | AC20: =IFERROR(AVERAGE(O20,P20,Q20,R20,S20),0) | AD20: =IF(T20="Y",ROW()-2,"")
A21: 19 | B21: Nefise Yaşar | C21: Other | D21: Electronics Engineering | E21: 3rd year | G21: Participated once | H21: 3 | I21: 2 | J21: 1 | K21: 4 | L21: 2 | M21: 4 | T21: N | U21: =IF(B21="","",(X21*Weights!$B$2+Y21*Weights!$B$3+Z21*Weights!$B$4+AA21*Weights!$B$5+AB21*Weights!$B$6+H21*Weights!$B$7+I21*Weights!$B$8+J21*Weights!$B$9+K21*Weights!$B$10+L21*Weights!$B$11+M21*Weights!$B$12+N21*Weights!$B$13+AC21*Weights!$B$14)/5) | V21: =IF(OR(B21="",T21="Y"),"",1+SUMPRODUCT(((U$3:U$32>U21)+((U$3:U$32=U21)*(ROW(U$3:U$32)<21)))*(T$3:T$32<>"Y")*(B$3:B$32<>""))) | W21: Kocaeli Üni Elektronik ve Haberleşme, 3.sınıf. Teknofest 2024 Savaşan İHA. Arduino projects. | X21: =IFERROR(VLOOKUP(VLOOKUP(C21,Uni_Tiers!$A$2:$B$24,2,FALSE()),Uni_Tiers!$E$2:$F$6,2,FALSE()),IF(C21="",1,2)) | Y21: =IFERROR(VLOOKUP(D21,Dept_Fit!$A$2:$B$15,2,FALSE()),1) | Z21: =IF(F21="",1,IF(F21>=3.5,5,IF(F21>=3,4,IF(F21>=2.5,3,IF(F21>=2,2,1))))) | AA21: =IFERROR(VLOOKUP(E21,Status_Map!$A$2:$B$9,2,FALSE()),1) | AB21: =IFERROR(VLOOKUP(G21,Teknofest_Map!$A$2:$B$6,2,FALSE()),1) | AC21: =IFERROR(AVERAGE(O21,P21,Q21,R21,S21),0) | AD21: =IF(T21="Y",ROW()-2,"")
A22: 20 | B22: Nisa Nur Çolak | C22: Yıldız Teknik | D22: Control Engineering | E22: 4th year | G22: None | H22: 2 | I22: 2 | J22: 3 | K22: 3 | L22: 1 | M22: 5 | T22: N | U22: =IF(B22="","",(X22*Weights!$B$2+Y22*Weights!$B$3+Z22*Weights!$B$4+AA22*Weights!$B$5+AB22*Weights!$B$6+H22*Weights!$B$7+I22*Weights!$B$8+J22*Weights!$B$9+K22*Weights!$B$10+L22*Weights!$B$11+M22*Weights!$B$12+N22*Weights!$B$13+AC22*Weights!$B$14)/5) | V22: =IF(OR(B22="",T22="Y"),"",1+SUMPRODUCT(((U$3:U$32>U22)+((U$3:U$32=U22)*(ROW(U$3:U$32)<22)))*(T$3:T$32<>"Y")*(B$3:B$32<>""))) | W22: YTU Control & Automation; YTU Racing VCU team (Vehicle Control Unit support). | X22: =IFERROR(VLOOKUP(VLOOKUP(C22,Uni_Tiers!$A$2:$B$24,2,FALSE()),Uni_Tiers!$E$2:$F$6,2,FALSE()),IF(C22="",1,2)) | Y22: =IFERROR(VLOOKUP(D22,Dept_Fit!$A$2:$B$15,2,FALSE()),1) | Z22: =IF(F22="",1,IF(F22>=3.5,5,IF(F22>=3,4,IF(F22>=2.5,3,IF(F22>=2,2,1))))) | AA22: =IFERROR(VLOOKUP(E22,Status_Map!$A$2:$B$9,2,FALSE()),1) | AB22: =IFERROR(VLOOKUP(G22,Teknofest_Map!$A$2:$B$6,2,FALSE()),1) | AC22: =IFERROR(AVERAGE(O22,P22,Q22,R22,S22),0) | AD22: =IF(T22="Y",ROW()-2,"")
A23: 21 | B23: Onur Can Sarı | C23: Other | D23: Computer Engineering | E23: 3rd year | G23: Podium / finals | H23: 5 | I23: 5 | J23: 5 | K23: 4 | L23: 4 | M23: 3 | T23: N | U23: =IF(B23="","",(X23*Weights!$B$2+Y23*Weights!$B$3+Z23*Weights!$B$4+AA23*Weights!$B$5+AB23*Weights!$B$6+H23*Weights!$B$7+I23*Weights!$B$8+J23*Weights!$B$9+K23*Weights!$B$10+L23*Weights!$B$11+M23*Weights!$B$12+N23*Weights!$B$13+AC23*Weights!$B$14)/5) | V23: =IF(OR(B23="",T23="Y"),"",1+SUMPRODUCT(((U$3:U$32>U23)+((U$3:U$32=U23)*(ROW(U$3:U$32)<23)))*(T$3:T$32<>"Y")*(B$3:B$32<>""))) | W23: Fırat Üni Bilgisayar Müh 3. sınıf. Markas Teknoloji (ROKETSAN sub) embedded software engineer; Ayyıldız air defense team. Teknofest Roket 'En İyi Takım' award. Very strong real-project record. | X23: =IFERROR(VLOOKUP(VLOOKUP(C23,Uni_Tiers!$A$2:$B$24,2,FALSE()),Uni_Tiers!$E$2:$F$6,2,FALSE()),IF(C23="",1,2)) | Y23: =IFERROR(VLOOKUP(D23,Dept_Fit!$A$2:$B$15,2,FALSE()),1) | Z23: =IF(F23="",1,IF(F23>=3.5,5,IF(F23>=3,4,IF(F23>=2.5,3,IF(F23>=2,2,1))))) | AA23: =IFERROR(VLOOKUP(E23,Status_Map!$A$2:$B$9,2,FALSE()),1) | AB23: =IFERROR(VLOOKUP(G23,Teknofest_Map!$A$2:$B$6,2,FALSE()),1) | AC23: =IFERROR(AVERAGE(O23,P23,Q23,R23,S23),0) | AD23: =IF(T23="Y",ROW()-2,"")
A24: 22 | B24: Ruba Almadi | C24: ITU | D24: Control Engineering | E24: 3rd year | G24: Podium / finals | H24: 4 | I24: 3 | J24: 2 | K24: 4 | L24: 2 | M24: 3 | T24: N | U24: =IF(B24="","",(X24*Weights!$B$2+Y24*Weights!$B$3+Z24*Weights!$B$4+AA24*Weights!$B$5+AB24*Weights!$B$6+H24*Weights!$B$7+I24*Weights!$B$8+J24*Weights!$B$9+K24*Weights!$B$10+L24*Weights!$B$11+M24*Weights!$B$12+N24*Weights!$B$13+AC24*Weights!$B$14)/5) | V24: =IF(OR(B24="",T24="Y"),"",1+SUMPRODUCT(((U$3:U$32>U24)+((U$3:U$32=U24)*(ROW(U$3:U$32)<24)))*(T$3:T$32<>"Y")*(B$3:B$32<>""))) | W24: ITU Control & Automation, 3rd year (started Sep 2023). Teknofest 2024 2nd place + Steel award; Hyperloop team (3× 1st place internationally). | X24: =IFERROR(VLOOKUP(VLOOKUP(C24,Uni_Tiers!$A$2:$B$24,2,FALSE()),Uni_Tiers!$E$2:$F$6,2,FALSE()),IF(C24="",1,2)) | Y24: =IFERROR(VLOOKUP(D24,Dept_Fit!$A$2:$B$15,2,FALSE()),1) | Z24: =IF(F24="",1,IF(F24>=3.5,5,IF(F24>=3,4,IF(F24>=2.5,3,IF(F24>=2,2,1))))) | AA24: =IFERROR(VLOOKUP(E24,Status_Map!$A$2:$B$9,2,FALSE()),1) | AB24: =IFERROR(VLOOKUP(G24,Teknofest_Map!$A$2:$B$6,2,FALSE()),1) | AC24: =IFERROR(AVERAGE(O24,P24,Q24,R24,S24),0) | AD24: =IF(T24="Y",ROW()-2,"")
A25: 23 | B25: Rüveyda Dilara Gülbaş | C25: Atılım | D25: Computer Engineering | E25: Fresh graduate (<1 yr) | F25: 3.25 | G25: Podium / finals | H25: 5 | I25: 5 | J25: 3 | K25: 5 | L25: 4 | M25: 3 | T25: N | U25: =IF(B25="","",(X25*Weights!$B$2+Y25*Weights!$B$3+Z25*Weights!$B$4+AA25*Weights!$B$5+AB25*Weights!$B$6+H25*Weights!$B$7+I25*Weights!$B$8+J25*Weights!$B$9+K25*Weights!$B$10+L25*Weights!$B$11+M25*Weights!$B$12+N25*Weights!$B$13+AC25*Weights!$B$14)/5) | V25: =IF(OR(B25="",T25="Y"),"",1+SUMPRODUCT(((U$3:U$32>U25)+((U$3:U$32=U25)*(ROW(U$3:U$32)<25)))*(T$3:T$32<>"Y")*(B$3:B$32<>""))) | W25: GNO 3.25/4. Teknofest 2024 Finalist – Tarımsal İKA (Unmanned Land Vehicle) Yarışması. Computer vision focus (YOLOv8/v10, DETR). | X25: =IFERROR(VLOOKUP(VLOOKUP(C25,Uni_Tiers!$A$2:$B$24,2,FALSE()),Uni_Tiers!$E$2:$F$6,2,FALSE()),IF(C25="",1,2)) | Y25: =IFERROR(VLOOKUP(D25,Dept_Fit!$A$2:$B$15,2,FALSE()),1) | Z25: =IF(F25="",1,IF(F25>=3.5,5,IF(F25>=3,4,IF(F25>=2.5,3,IF(F25>=2,2,1))))) | AA25: =IFERROR(VLOOKUP(E25,Status_Map!$A$2:$B$9,2,FALSE()),1) | AB25: =IFERROR(VLOOKUP(G25,Teknofest_Map!$A$2:$B$6,2,FALSE()),1) | AC25: =IFERROR(AVERAGE(O25,P25,Q25,R25,S25),0) | AD25: =IF(T25="Y",ROW()-2,"")
A26: 24 | B26: Samet Atak | C26: ITU | D26: Control Engineering | E26: 4th year | G26: Podium / finals | H26: 3 | I26: 2 | J26: 1 | K26: 4 | L26: 1 | M26: 5 | T26: N | U26: =IF(B26="","",(X26*Weights!$B$2+Y26*Weights!$B$3+Z26*Weights!$B$4+AA26*Weights!$B$5+AB26*Weights!$B$6+H26*Weights!$B$7+I26*Weights!$B$8+J26*Weights!$B$9+K26*Weights!$B$10+L26*Weights!$B$11+M26*Weights!$B$12+N26*Weights!$B$13+AC26*Weights!$B$14)/5) | V26: =IF(OR(B26="",T26="Y"),"",1+SUMPRODUCT(((U$3:U$32>U26)+((U$3:U$32=U26)*(ROW(U$3:U$32)<26)))*(T$3:T$32<>"Y")*(B$3:B$32<>""))) | W26: ITU Control & Automation 2022-; Erasmus at U. of Kassel; Yıldız Teknopark Machine ArGe. Finalist Teknofest TIKA Competition. | X26: =IFERROR(VLOOKUP(VLOOKUP(C26,Uni_Tiers!$A$2:$B$24,2,FALSE()),Uni_Tiers!$E$2:$F$6,2,FALSE()),IF(C26="",1,2)) | Y26: =IFERROR(VLOOKUP(D26,Dept_Fit!$A$2:$B$15,2,FALSE()),1) | Z26: =IF(F26="",1,IF(F26>=3.5,5,IF(F26>=3,4,IF(F26>=2.5,3,IF(F26>=2,2,1))))) | AA26: =IFERROR(VLOOKUP(E26,Status_Map!$A$2:$B$9,2,FALSE()),1) | AB26: =IFERROR(VLOOKUP(G26,Teknofest_Map!$A$2:$B$6,2,FALSE()),1) | AC26: =IFERROR(AVERAGE(O26,P26,Q26,R26,S26),0) | AD26: =IF(T26="Y",ROW()-2,"")
A27: 25 | B27: Sefa Demirtürk | C27: Other | D27: Other | E27: Fresh graduate (<1 yr) | G27: Participated once | H27: 2 | I27: 2 | J27: 1 | K27: 3 | L27: 4 | M27: 3 | T27: N | U27: =IF(B27="","",(X27*Weights!$B$2+Y27*Weights!$B$3+Z27*Weights!$B$4+AA27*Weights!$B$5+AB27*Weights!$B$6+H27*Weights!$B$7+I27*Weights!$B$8+J27*Weights!$B$9+K27*Weights!$B$10+L27*Weights!$B$11+M27*Weights!$B$12+N27*Weights!$B$13+AC27*Weights!$B$14)/5) | V27: =IF(OR(B27="",T27="Y"),"",1+SUMPRODUCT(((U$3:U$32>U27)+((U$3:U$32=U27)*(ROW(U$3:U$32)<27)))*(T$3:T$32<>"Y")*(B$3:B$32<>""))) | W27: Gebze Technical University 2019-2026. ML/CV (OpenCV, YOLOv5, Pandas). Teknofest 2021 Autonomous Marine Cleaning Vehicle. | X27: =IFERROR(VLOOKUP(VLOOKUP(C27,Uni_Tiers!$A$2:$B$24,2,FALSE()),Uni_Tiers!$E$2:$F$6,2,FALSE()),IF(C27="",1,2)) | Y27: =IFERROR(VLOOKUP(D27,Dept_Fit!$A$2:$B$15,2,FALSE()),1) | Z27: =IF(F27="",1,IF(F27>=3.5,5,IF(F27>=3,4,IF(F27>=2.5,3,IF(F27>=2,2,1))))) | AA27: =IFERROR(VLOOKUP(E27,Status_Map!$A$2:$B$9,2,FALSE()),1) | AB27: =IFERROR(VLOOKUP(G27,Teknofest_Map!$A$2:$B$6,2,FALSE()),1) | AC27: =IFERROR(AVERAGE(O27,P27,Q27,R27,S27),0) | AD27: =IF(T27="Y",ROW()-2,"")
A28: 26 | B28: Servet Haras | C28: Other | D28: Electrical & Electronics Engineering | E28: 3rd year | F28: 3.91 | G28: Participated once | H28: 3 | I28: 4 | J28: 3 | K28: 4 | L28: 2 | M28: 4 | T28: N | U28: =IF(B28="","",(X28*Weights!$B$2+Y28*Weights!$B$3+Z28*Weights!$B$4+AA28*Weights!$B$5+AB28*Weights!$B$6+H28*Weights!$B$7+I28*Weights!$B$8+J28*Weights!$B$9+K28*Weights!$B$10+L28*Weights!$B$11+M28*Weights!$B$12+N28*Weights!$B$13+AC28*Weights!$B$14)/5) | V28: =IF(OR(B28="",T28="Y"),"",1+SUMPRODUCT(((U$3:U$32>U28)+((U$3:U$32=U28)*(ROW(U$3:U$32)<28)))*(T$3:T$32<>"Y")*(B$3:B$32<>""))) | W28: Kadir Has Üni EEE 3. sınıf, GPA 3.91 (full scholarship). Teknofest Otonom Robotaksi BMS / battery design. | X28: =IFERROR(VLOOKUP(VLOOKUP(C28,Uni_Tiers!$A$2:$B$24,2,FALSE()),Uni_Tiers!$E$2:$F$6,2,FALSE()),IF(C28="",1,2)) | Y28: =IFERROR(VLOOKUP(D28,Dept_Fit!$A$2:$B$15,2,FALSE()),1) | Z28: =IF(F28="",1,IF(F28>=3.5,5,IF(F28>=3,4,IF(F28>=2.5,3,IF(F28>=2,2,1))))) | AA28: =IFERROR(VLOOKUP(E28,Status_Map!$A$2:$B$9,2,FALSE()),1) | AB28: =IFERROR(VLOOKUP(G28,Teknofest_Map!$A$2:$B$6,2,FALSE()),1) | AC28: =IFERROR(AVERAGE(O28,P28,Q28,R28,S28),0) | AD28: =IF(T28="Y",ROW()-2,"")
A29: 27 | B29: Simar Bayramusta | C29: Other | D29: Other | G29: None | H29: 1 | I29: 2 | J29: 1 | K29: 1 | L29: 1 | M29: 3 | T29: N | U29: =IF(B29="","",(X29*Weights!$B$2+Y29*Weights!$B$3+Z29*Weights!$B$4+AA29*Weights!$B$5+AB29*Weights!$B$6+H29*Weights!$B$7+I29*Weights!$B$8+J29*Weights!$B$9+K29*Weights!$B$10+L29*Weights!$B$11+M29*Weights!$B$12+N29*Weights!$B$13+AC29*Weights!$B$14)/5) | V29: =IF(OR(B29="",T29="Y"),"",1+SUMPRODUCT(((U$3:U$32>U29)+((U$3:U$32=U29)*(ROW(U$3:U$32)<29)))*(T$3:T$32<>"Y")*(B$3:B$32<>""))) | W29: PDF appears image-only — text extraction yielded almost nothing. Re-OCR required before scoring. All numeric scores left at default heuristic (1) for now. | X29: =IFERROR(VLOOKUP(VLOOKUP(C29,Uni_Tiers!$A$2:$B$24,2,FALSE()),Uni_Tiers!$E$2:$F$6,2,FALSE()),IF(C29="",1,2)) | Y29: =IFERROR(VLOOKUP(D29,Dept_Fit!$A$2:$B$15,2,FALSE()),1) | Z29: =IF(F29="",1,IF(F29>=3.5,5,IF(F29>=3,4,IF(F29>=2.5,3,IF(F29>=2,2,1))))) | AA29: =IFERROR(VLOOKUP(E29,Status_Map!$A$2:$B$9,2,FALSE()),1) | AB29: =IFERROR(VLOOKUP(G29,Teknofest_Map!$A$2:$B$6,2,FALSE()),1) | AC29: =IFERROR(AVERAGE(O29,P29,Q29,R29,S29),0) | AD29: =IF(T29="Y",ROW()-2,"")
A30: 28 | B30: Tasneem Mustafa | C30: ITU | D30: Control Engineering | E30: 3rd year | G30: Podium / finals | H30: 5 | I30: 2 | J30: 1 | K30: 5 | L30: 4 | M30: 3 | T30: N | U30: =IF(B30="","",(X30*Weights!$B$2+Y30*Weights!$B$3+Z30*Weights!$B$4+AA30*Weights!$B$5+AB30*Weights!$B$6+H30*Weights!$B$7+I30*Weights!$B$8+J30*Weights!$B$9+K30*Weights!$B$10+L30*Weights!$B$11+M30*Weights!$B$12+N30*Weights!$B$13+AC30*Weights!$B$14)/5) | V30: =IF(OR(B30="",T30="Y"),"",1+SUMPRODUCT(((U$3:U$32>U30)+((U$3:U$32=U30)*(ROW(U$3:U$32)<30)))*(T$3:T$32<>"Y")*(B$3:B$32<>""))) | W30: ITU Control & Automation Sep 2023-present; BAYKAR intern (Autopilot & Intelligent Systems Software, Jun 2026-). XENOS Robotaksi Teknofest Finalist 2024-25; MATLAB MiniDrone Finalist. | X30: =IFERROR(VLOOKUP(VLOOKUP(C30,Uni_Tiers!$A$2:$B$24,2,FALSE()),Uni_Tiers!$E$2:$F$6,2,FALSE()),IF(C30="",1,2)) | Y30: =IFERROR(VLOOKUP(D30,Dept_Fit!$A$2:$B$15,2,FALSE()),1) | Z30: =IF(F30="",1,IF(F30>=3.5,5,IF(F30>=3,4,IF(F30>=2.5,3,IF(F30>=2,2,1))))) | AA30: =IFERROR(VLOOKUP(E30,Status_Map!$A$2:$B$9,2,FALSE()),1) | AB30: =IFERROR(VLOOKUP(G30,Teknofest_Map!$A$2:$B$6,2,FALSE()),1) | AC30: =IFERROR(AVERAGE(O30,P30,Q30,R30,S30),0) | AD30: =IF(T30="Y",ROW()-2,"")
A31: 29 | B31: Yehya Elnoti | C31: Other | D31: Aerospace Engineering | E31: 3rd year | F31: 2.61 | G31: Podium / finals | H31: 5 | I31: 4 | J31: 4 | K31: 5 | L31: 5 | M31: 5 | T31: N | U31: =IF(B31="","",(X31*Weights!$B$2+Y31*Weights!$B$3+Z31*Weights!$B$4+AA31*Weights!$B$5+AB31*Weights!$B$6+H31*Weights!$B$7+I31*Weights!$B$8+J31*Weights!$B$9+K31*Weights!$B$10+L31*Weights!$B$11+M31*Weights!$B$12+N31*Weights!$B$13+AC31*Weights!$B$14)/5) | V31: =IF(OR(B31="",T31="Y"),"",1+SUMPRODUCT(((U$3:U$32>U31)+((U$3:U$32=U31)*(ROW(U$3:U$32)<31)))*(T$3:T$32<>"Y")*(B$3:B$32<>""))) | W31: Istanbul Aydın Üni Aerospace 3rd year, GPA 2.61. Teknofest Fighter UAV 2025 JETDOSE team lead (9 members) – finals. | X31: =IFERROR(VLOOKUP(VLOOKUP(C31,Uni_Tiers!$A$2:$B$24,2,FALSE()),Uni_Tiers!$E$2:$F$6,2,FALSE()),IF(C31="",1,2)) | Y31: =IFERROR(VLOOKUP(D31,Dept_Fit!$A$2:$B$15,2,FALSE()),1) | Z31: =IF(F31="",1,IF(F31>=3.5,5,IF(F31>=3,4,IF(F31>=2.5,3,IF(F31>=2,2,1))))) | AA31: =IFERROR(VLOOKUP(E31,Status_Map!$A$2:$B$9,2,FALSE()),1) | AB31: =IFERROR(VLOOKUP(G31,Teknofest_Map!$A$2:$B$6,2,FALSE()),1) | AC31: =IFERROR(AVERAGE(O31,P31,Q31,R31,S31),0) | AD31: =IF(T31="Y",ROW()-2,"")
A32: 30 | B32: Yusuf Han Kızıltepe | C32: Other | D32: Electrical & Electronics Engineering | E32: 4th year | G32: None | H32: 2 | I32: 2 | J32: 1 | K32: 3 | L32: 1 | M32: 3 | T32: N | U32: =IF(B32="","",(X32*Weights!$B$2+Y32*Weights!$B$3+Z32*Weights!$B$4+AA32*Weights!$B$5+AB32*Weights!$B$6+H32*Weights!$B$7+I32*Weights!$B$8+J32*Weights!$B$9+K32*Weights!$B$10+L32*Weights!$B$11+M32*Weights!$B$12+N32*Weights!$B$13+AC32*Weights!$B$14)/5) | V32: =IF(OR(B32="",T32="Y"),"",1+SUMPRODUCT(((U$3:U$32>U32)+((U$3:U$32=U32)*(ROW(U$3:U$32)<32)))*(T$3:T$32<>"Y")*(B$3:B$32<>""))) | W32: Manisa Celal Bayar Üni EEE son sınıf. Altium PCB, STM32 embedded, BMS hardware. Limited GNC/UAV exposure. | X32: =IFERROR(VLOOKUP(VLOOKUP(C32,Uni_Tiers!$A$2:$B$24,2,FALSE()),Uni_Tiers!$E$2:$F$6,2,FALSE()),IF(C32="",1,2)) | Y32: =IFERROR(VLOOKUP(D32,Dept_Fit!$A$2:$B$15,2,FALSE()),1) | Z32: =IF(F32="",1,IF(F32>=3.5,5,IF(F32>=3,4,IF(F32>=2.5,3,IF(F32>=2,2,1))))) | AA32: =IFERROR(VLOOKUP(E32,Status_Map!$A$2:$B$9,2,FALSE()),1) | AB32: =IFERROR(VLOOKUP(G32,Teknofest_Map!$A$2:$B$6,2,FALSE()),1) | AC32: =IFERROR(AVERAGE(O32,P32,Q32,R32,S32),0) | AD32: =IF(T32="Y",ROW()-2,"")

Sheet Ranking
A1: Rank | B1: Name | C1: University | D1: Department | E1: Status | F1: GPA | G1: Weighted Score | H1: Disqualified?
A2: 1 | B2: {=IFERROR(INDEX(Scoring!B$3:B$32,MATCH(1,Scoring!V$3:V$32,0)),"")} | C2: {=IFERROR(INDEX(Scoring!C$3:C$32,MATCH(1,Scoring!V$3:V$32,0)),"")} | D2: {=IFERROR(INDEX(Scoring!D$3:D$32,MATCH(1,Scoring!V$3:V$32,0)),"")} | E2: {=IFERROR(INDEX(Scoring!E$3:E$32,MATCH(1,Scoring!V$3:V$32,0)),"")} | F2: {=IFERROR(INDEX(Scoring!F$3:F$32,MATCH(1,Scoring!V$3:V$32,0)),"")} | G2: {=IFERROR(INDEX(Scoring!U$3:U$32,MATCH(1,Scoring!V$3:V$32,0)),"")} | H2: {=IFERROR(INDEX(Scoring!T$3:T$32,MATCH(1,Scoring!V$3:V$32,0)),"")}
A3: 2 | B3: {=IFERROR(INDEX(Scoring!B$3:B$32,MATCH(2,Scoring!V$3:V$32,0)),"")} | C3: {=IFERROR(INDEX(Scoring!C$3:C$32,MATCH(2,Scoring!V$3:V$32,0)),"")} | D3: {=IFERROR(INDEX(Scoring!D$3:D$32,MATCH(2,Scoring!V$3:V$32,0)),"")} | E3: {=IFERROR(INDEX(Scoring!E$3:E$32,MATCH(2,Scoring!V$3:V$32,0)),"")} | F3: {=IFERROR(INDEX(Scoring!F$3:F$32,MATCH(2,Scoring!V$3:V$32,0)),"")} | G3: {=IFERROR(INDEX(Scoring!U$3:U$32,MATCH(2,Scoring!V$3:V$32,0)),"")} | H3: {=IFERROR(INDEX(Scoring!T$3:T$32,MATCH(2,Scoring!V$3:V$32,0)),"")}
A4: 3 | B4: {=IFERROR(INDEX(Scoring!B$3:B$32,MATCH(3,Scoring!V$3:V$32,0)),"")} | C4: {=IFERROR(INDEX(Scoring!C$3:C$32,MATCH(3,Scoring!V$3:V$32,0)),"")} | D4: {=IFERROR(INDEX(Scoring!D$3:D$32,MATCH(3,Scoring!V$3:V$32,0)),"")} | E4: {=IFERROR(INDEX(Scoring!E$3:E$32,MATCH(3,Scoring!V$3:V$32,0)),"")} | F4: {=IFERROR(INDEX(Scoring!F$3:F$32,MATCH(3,Scoring!V$3:V$32,0)),"")} | G4: {=IFERROR(INDEX(Scoring!U$3:U$32,MATCH(3,Scoring!V$3:V$32,0)),"")} | H4: {=IFERROR(INDEX(Scoring!T$3:T$32,MATCH(3,Scoring!V$3:V$32,0)),"")}
A5: 4 | B5: {=IFERROR(INDEX(Scoring!B$3:B$32,MATCH(4,Scoring!V$3:V$32,0)),"")} | C5: {=IFERROR(INDEX(Scoring!C$3:C$32,MATCH(4,Scoring!V$3:V$32,0)),"")} | D5: {=IFERROR(INDEX(Scoring!D$3:D$32,MATCH(4,Scoring!V$3:V$32,0)),"")} | E5: {=IFERROR(INDEX(Scoring!E$3:E$32,MATCH(4,Scoring!V$3:V$32,0)),"")} | F5: {=IFERROR(INDEX(Scoring!F$3:F$32,MATCH(4,Scoring!V$3:V$32,0)),"")} | G5: {=IFERROR(INDEX(Scoring!U$3:U$32,MATCH(4,Scoring!V$3:V$32,0)),"")} | H5: {=IFERROR(INDEX(Scoring!T$3:T$32,MATCH(4,Scoring!V$3:V$32,0)),"")}
A6: 5 | B6: {=IFERROR(INDEX(Scoring!B$3:B$32,MATCH(5,Scoring!V$3:V$32,0)),"")} | C6: {=IFERROR(INDEX(Scoring!C$3:C$32,MATCH(5,Scoring!V$3:V$32,0)),"")} | D6: {=IFERROR(INDEX(Scoring!D$3:D$32,MATCH(5,Scoring!V$3:V$32,0)),"")} | E6: {=IFERROR(INDEX(Scoring!E$3:E$32,MATCH(5,Scoring!V$3:V$32,0)),"")} | F6: {=IFERROR(INDEX(Scoring!F$3:F$32,MATCH(5,Scoring!V$3:V$32,0)),"")} | G6: {=IFERROR(INDEX(Scoring!U$3:U$32,MATCH(5,Scoring!V$3:V$32,0)),"")} | H6: {=IFERROR(INDEX(Scoring!T$3:T$32,MATCH(5,Scoring!V$3:V$32,0)),"")}
A7: 6 | B7: {=IFERROR(INDEX(Scoring!B$3:B$32,MATCH(6,Scoring!V$3:V$32,0)),"")} | C7: {=IFERROR(INDEX(Scoring!C$3:C$32,MATCH(6,Scoring!V$3:V$32,0)),"")} | D7: {=IFERROR(INDEX(Scoring!D$3:D$32,MATCH(6,Scoring!V$3:V$32,0)),"")} | E7: {=IFERROR(INDEX(Scoring!E$3:E$32,MATCH(6,Scoring!V$3:V$32,0)),"")} | F7: {=IFERROR(INDEX(Scoring!F$3:F$32,MATCH(6,Scoring!V$3:V$32,0)),"")} | G7: {=IFERROR(INDEX(Scoring!U$3:U$32,MATCH(6,Scoring!V$3:V$32,0)),"")} | H7: {=IFERROR(INDEX(Scoring!T$3:T$32,MATCH(6,Scoring!V$3:V$32,0)),"")}
A8: 7 | B8: {=IFERROR(INDEX(Scoring!B$3:B$32,MATCH(7,Scoring!V$3:V$32,0)),"")} | C8: {=IFERROR(INDEX(Scoring!C$3:C$32,MATCH(7,Scoring!V$3:V$32,0)),"")} | D8: {=IFERROR(INDEX(Scoring!D$3:D$32,MATCH(7,Scoring!V$3:V$32,0)),"")} | E8: {=IFERROR(INDEX(Scoring!E$3:E$32,MATCH(7,Scoring!V$3:V$32,0)),"")} | F8: {=IFERROR(INDEX(Scoring!F$3:F$32,MATCH(7,Scoring!V$3:V$32,0)),"")} | G8: {=IFERROR(INDEX(Scoring!U$3:U$32,MATCH(7,Scoring!V$3:V$32,0)),"")} | H8: {=IFERROR(INDEX(Scoring!T$3:T$32,MATCH(7,Scoring!V$3:V$32,0)),"")}
A9: 8 | B9: {=IFERROR(INDEX(Scoring!B$3:B$32,MATCH(8,Scoring!V$3:V$32,0)),"")} | C9: {=IFERROR(INDEX(Scoring!C$3:C$32,MATCH(8,Scoring!V$3:V$32,0)),"")} | D9: {=IFERROR(INDEX(Scoring!D$3:D$32,MATCH(8,Scoring!V$3:V$32,0)),"")} | E9: {=IFERROR(INDEX(Scoring!E$3:E$32,MATCH(8,Scoring!V$3:V$32,0)),"")} | F9: {=IFERROR(INDEX(Scoring!F$3:F$32,MATCH(8,Scoring!V$3:V$32,0)),"")} | G9: {=IFERROR(INDEX(Scoring!U$3:U$32,MATCH(8,Scoring!V$3:V$32,0)),"")} | H9: {=IFERROR(INDEX(Scoring!T$3:T$32,MATCH(8,Scoring!V$3:V$32,0)),"")}
A10: 9 | B10: {=IFERROR(INDEX(Scoring!B$3:B$32,MATCH(9,Scoring!V$3:V$32,0)),"")} | C10: {=IFERROR(INDEX(Scoring!C$3:C$32,MATCH(9,Scoring!V$3:V$32,0)),"")} | D10: {=IFERROR(INDEX(Scoring!D$3:D$32,MATCH(9,Scoring!V$3:V$32,0)),"")} | E10: {=IFERROR(INDEX(Scoring!E$3:E$32,MATCH(9,Scoring!V$3:V$32,0)),"")} | F10: {=IFERROR(INDEX(Scoring!F$3:F$32,MATCH(9,Scoring!V$3:V$32,0)),"")} | G10: {=IFERROR(INDEX(Scoring!U$3:U$32,MATCH(9,Scoring!V$3:V$32,0)),"")} | H10: {=IFERROR(INDEX(Scoring!T$3:T$32,MATCH(9,Scoring!V$3:V$32,0)),"")}
A11: 10 | B11: {=IFERROR(INDEX(Scoring!B$3:B$32,MATCH(10,Scoring!V$3:V$32,0)),"")} | C11: {=IFERROR(INDEX(Scoring!C$3:C$32,MATCH(10,Scoring!V$3:V$32,0)),"")} | D11: {=IFERROR(INDEX(Scoring!D$3:D$32,MATCH(10,Scoring!V$3:V$32,0)),"")} | E11: {=IFERROR(INDEX(Scoring!E$3:E$32,MATCH(10,Scoring!V$3:V$32,0)),"")} | F11: {=IFERROR(INDEX(Scoring!F$3:F$32,MATCH(10,Scoring!V$3:V$32,0)),"")} | G11: {=IFERROR(INDEX(Scoring!U$3:U$32,MATCH(10,Scoring!V$3:V$32,0)),"")} | H11: {=IFERROR(INDEX(Scoring!T$3:T$32,MATCH(10,Scoring!V$3:V$32,0)),"")}
A12: 11 | B12: {=IFERROR(INDEX(Scoring!B$3:B$32,MATCH(11,Scoring!V$3:V$32,0)),"")} | C12: {=IFERROR(INDEX(Scoring!C$3:C$32,MATCH(11,Scoring!V$3:V$32,0)),"")} | D12: {=IFERROR(INDEX(Scoring!D$3:D$32,MATCH(11,Scoring!V$3:V$32,0)),"")} | E12: {=IFERROR(INDEX(Scoring!E$3:E$32,MATCH(11,Scoring!V$3:V$32,0)),"")} | F12: {=IFERROR(INDEX(Scoring!F$3:F$32,MATCH(11,Scoring!V$3:V$32,0)),"")} | G12: {=IFERROR(INDEX(Scoring!U$3:U$32,MATCH(11,Scoring!V$3:V$32,0)),"")} | H12: {=IFERROR(INDEX(Scoring!T$3:T$32,MATCH(11,Scoring!V$3:V$32,0)),"")}
A13: 12 | B13: {=IFERROR(INDEX(Scoring!B$3:B$32,MATCH(12,Scoring!V$3:V$32,0)),"")} | C13: {=IFERROR(INDEX(Scoring!C$3:C$32,MATCH(12,Scoring!V$3:V$32,0)),"")} | D13: {=IFERROR(INDEX(Scoring!D$3:D$32,MATCH(12,Scoring!V$3:V$32,0)),"")} | E13: {=IFERROR(INDEX(Scoring!E$3:E$32,MATCH(12,Scoring!V$3:V$32,0)),"")} | F13: {=IFERROR(INDEX(Scoring!F$3:F$32,MATCH(12,Scoring!V$3:V$32,0)),"")} | G13: {=IFERROR(INDEX(Scoring!U$3:U$32,MATCH(12,Scoring!V$3:V$32,0)),"")} | H13: {=IFERROR(INDEX(Scoring!T$3:T$32,MATCH(12,Scoring!V$3:V$32,0)),"")}
A14: 13 | B14: {=IFERROR(INDEX(Scoring!B$3:B$32,MATCH(13,Scoring!V$3:V$32,0)),"")} | C14: {=IFERROR(INDEX(Scoring!C$3:C$32,MATCH(13,Scoring!V$3:V$32,0)),"")} | D14: {=IFERROR(INDEX(Scoring!D$3:D$32,MATCH(13,Scoring!V$3:V$32,0)),"")} | E14: {=IFERROR(INDEX(Scoring!E$3:E$32,MATCH(13,Scoring!V$3:V$32,0)),"")} | F14: {=IFERROR(INDEX(Scoring!F$3:F$32,MATCH(13,Scoring!V$3:V$32,0)),"")} | G14: {=IFERROR(INDEX(Scoring!U$3:U$32,MATCH(13,Scoring!V$3:V$32,0)),"")} | H14: {=IFERROR(INDEX(Scoring!T$3:T$32,MATCH(13,Scoring!V$3:V$32,0)),"")}
A15: 14 | B15: {=IFERROR(INDEX(Scoring!B$3:B$32,MATCH(14,Scoring!V$3:V$32,0)),"")} | C15: {=IFERROR(INDEX(Scoring!C$3:C$32,MATCH(14,Scoring!V$3:V$32,0)),"")} | D15: {=IFERROR(INDEX(Scoring!D$3:D$32,MATCH(14,Scoring!V$3:V$32,0)),"")} | E15: {=IFERROR(INDEX(Scoring!E$3:E$32,MATCH(14,Scoring!V$3:V$32,0)),"")} | F15: {=IFERROR(INDEX(Scoring!F$3:F$32,MATCH(14,Scoring!V$3:V$32,0)),"")} | G15: {=IFERROR(INDEX(Scoring!U$3:U$32,MATCH(14,Scoring!V$3:V$32,0)),"")} | H15: {=IFERROR(INDEX(Scoring!T$3:T$32,MATCH(14,Scoring!V$3:V$32,0)),"")}
A16: 15 | B16: {=IFERROR(INDEX(Scoring!B$3:B$32,MATCH(15,Scoring!V$3:V$32,0)),"")} | C16: {=IFERROR(INDEX(Scoring!C$3:C$32,MATCH(15,Scoring!V$3:V$32,0)),"")} | D16: {=IFERROR(INDEX(Scoring!D$3:D$32,MATCH(15,Scoring!V$3:V$32,0)),"")} | E16: {=IFERROR(INDEX(Scoring!E$3:E$32,MATCH(15,Scoring!V$3:V$32,0)),"")} | F16: {=IFERROR(INDEX(Scoring!F$3:F$32,MATCH(15,Scoring!V$3:V$32,0)),"")} | G16: {=IFERROR(INDEX(Scoring!U$3:U$32,MATCH(15,Scoring!V$3:V$32,0)),"")} | H16: {=IFERROR(INDEX(Scoring!T$3:T$32,MATCH(15,Scoring!V$3:V$32,0)),"")}
A17: 16 | B17: {=IFERROR(INDEX(Scoring!B$3:B$32,MATCH(16,Scoring!V$3:V$32,0)),"")} | C17: {=IFERROR(INDEX(Scoring!C$3:C$32,MATCH(16,Scoring!V$3:V$32,0)),"")} | D17: {=IFERROR(INDEX(Scoring!D$3:D$32,MATCH(16,Scoring!V$3:V$32,0)),"")} | E17: {=IFERROR(INDEX(Scoring!E$3:E$32,MATCH(16,Scoring!V$3:V$32,0)),"")} | F17: {=IFERROR(INDEX(Scoring!F$3:F$32,MATCH(16,Scoring!V$3:V$32,0)),"")} | G17: {=IFERROR(INDEX(Scoring!U$3:U$32,MATCH(16,Scoring!V$3:V$32,0)),"")} | H17: {=IFERROR(INDEX(Scoring!T$3:T$32,MATCH(16,Scoring!V$3:V$32,0)),"")}
A18: 17 | B18: {=IFERROR(INDEX(Scoring!B$3:B$32,MATCH(17,Scoring!V$3:V$32,0)),"")} | C18: {=IFERROR(INDEX(Scoring!C$3:C$32,MATCH(17,Scoring!V$3:V$32,0)),"")} | D18: {=IFERROR(INDEX(Scoring!D$3:D$32,MATCH(17,Scoring!V$3:V$32,0)),"")} | E18: {=IFERROR(INDEX(Scoring!E$3:E$32,MATCH(17,Scoring!V$3:V$32,0)),"")} | F18: {=IFERROR(INDEX(Scoring!F$3:F$32,MATCH(17,Scoring!V$3:V$32,0)),"")} | G18: {=IFERROR(INDEX(Scoring!U$3:U$32,MATCH(17,Scoring!V$3:V$32,0)),"")} | H18: {=IFERROR(INDEX(Scoring!T$3:T$32,MATCH(17,Scoring!V$3:V$32,0)),"")}
A19: 18 | B19: {=IFERROR(INDEX(Scoring!B$3:B$32,MATCH(18,Scoring!V$3:V$32,0)),"")} | C19: {=IFERROR(INDEX(Scoring!C$3:C$32,MATCH(18,Scoring!V$3:V$32,0)),"")} | D19: {=IFERROR(INDEX(Scoring!D$3:D$32,MATCH(18,Scoring!V$3:V$32,0)),"")} | E19: {=IFERROR(INDEX(Scoring!E$3:E$32,MATCH(18,Scoring!V$3:V$32,0)),"")} | F19: {=IFERROR(INDEX(Scoring!F$3:F$32,MATCH(18,Scoring!V$3:V$32,0)),"")} | G19: {=IFERROR(INDEX(Scoring!U$3:U$32,MATCH(18,Scoring!V$3:V$32,0)),"")} | H19: {=IFERROR(INDEX(Scoring!T$3:T$32,MATCH(18,Scoring!V$3:V$32,0)),"")}
A20: 19 | B20: {=IFERROR(INDEX(Scoring!B$3:B$32,MATCH(19,Scoring!V$3:V$32,0)),"")} | C20: {=IFERROR(INDEX(Scoring!C$3:C$32,MATCH(19,Scoring!V$3:V$32,0)),"")} | D20: {=IFERROR(INDEX(Scoring!D$3:D$32,MATCH(19,Scoring!V$3:V$32,0)),"")} | E20: {=IFERROR(INDEX(Scoring!E$3:E$32,MATCH(19,Scoring!V$3:V$32,0)),"")} | F20: {=IFERROR(INDEX(Scoring!F$3:F$32,MATCH(19,Scoring!V$3:V$32,0)),"")} | G20: {=IFERROR(INDEX(Scoring!U$3:U$32,MATCH(19,Scoring!V$3:V$32,0)),"")} | H20: {=IFERROR(INDEX(Scoring!T$3:T$32,MATCH(19,Scoring!V$3:V$32,0)),"")}
A21: 20 | B21: {=IFERROR(INDEX(Scoring!B$3:B$32,MATCH(20,Scoring!V$3:V$32,0)),"")} | C21: {=IFERROR(INDEX(Scoring!C$3:C$32,MATCH(20,Scoring!V$3:V$32,0)),"")} | D21: {=IFERROR(INDEX(Scoring!D$3:D$32,MATCH(20,Scoring!V$3:V$32,0)),"")} | E21: {=IFERROR(INDEX(Scoring!E$3:E$32,MATCH(20,Scoring!V$3:V$32,0)),"")} | F21: {=IFERROR(INDEX(Scoring!F$3:F$32,MATCH(20,Scoring!V$3:V$32,0)),"")} | G21: {=IFERROR(INDEX(Scoring!U$3:U$32,MATCH(20,Scoring!V$3:V$32,0)),"")} | H21: {=IFERROR(INDEX(Scoring!T$3:T$32,MATCH(20,Scoring!V$3:V$32,0)),"")}
A22: 21 | B22: {=IFERROR(INDEX(Scoring!B$3:B$32,MATCH(21,Scoring!V$3:V$32,0)),"")} | C22: {=IFERROR(INDEX(Scoring!C$3:C$32,MATCH(21,Scoring!V$3:V$32,0)),"")} | D22: {=IFERROR(INDEX(Scoring!D$3:D$32,MATCH(21,Scoring!V$3:V$32,0)),"")} | E22: {=IFERROR(INDEX(Scoring!E$3:E$32,MATCH(21,Scoring!V$3:V$32,0)),"")} | F22: {=IFERROR(INDEX(Scoring!F$3:F$32,MATCH(21,Scoring!V$3:V$32,0)),"")} | G22: {=IFERROR(INDEX(Scoring!U$3:U$32,MATCH(21,Scoring!V$3:V$32,0)),"")} | H22: {=IFERROR(INDEX(Scoring!T$3:T$32,MATCH(21,Scoring!V$3:V$32,0)),"")}
A23: 22 | B23: {=IFERROR(INDEX(Scoring!B$3:B$32,MATCH(22,Scoring!V$3:V$32,0)),"")} | C23: {=IFERROR(INDEX(Scoring!C$3:C$32,MATCH(22,Scoring!V$3:V$32,0)),"")} | D23: {=IFERROR(INDEX(Scoring!D$3:D$32,MATCH(22,Scoring!V$3:V$32,0)),"")} | E23: {=IFERROR(INDEX(Scoring!E$3:E$32,MATCH(22,Scoring!V$3:V$32,0)),"")} | F23: {=IFERROR(INDEX(Scoring!F$3:F$32,MATCH(22,Scoring!V$3:V$32,0)),"")} | G23: {=IFERROR(INDEX(Scoring!U$3:U$32,MATCH(22,Scoring!V$3:V$32,0)),"")} | H23: {=IFERROR(INDEX(Scoring!T$3:T$32,MATCH(22,Scoring!V$3:V$32,0)),"")}
A24: 23 | B24: {=IFERROR(INDEX(Scoring!B$3:B$32,MATCH(23,Scoring!V$3:V$32,0)),"")} | C24: {=IFERROR(INDEX(Scoring!C$3:C$32,MATCH(23,Scoring!V$3:V$32,0)),"")} | D24: {=IFERROR(INDEX(Scoring!D$3:D$32,MATCH(23,Scoring!V$3:V$32,0)),"")} | E24: {=IFERROR(INDEX(Scoring!E$3:E$32,MATCH(23,Scoring!V$3:V$32,0)),"")} | F24: {=IFERROR(INDEX(Scoring!F$3:F$32,MATCH(23,Scoring!V$3:V$32,0)),"")} | G24: {=IFERROR(INDEX(Scoring!U$3:U$32,MATCH(23,Scoring!V$3:V$32,0)),"")} | H24: {=IFERROR(INDEX(Scoring!T$3:T$32,MATCH(23,Scoring!V$3:V$32,0)),"")}
A25: 24 | B25: {=IFERROR(INDEX(Scoring!B$3:B$32,MATCH(24,Scoring!V$3:V$32,0)),"")} | C25: {=IFERROR(INDEX(Scoring!C$3:C$32,MATCH(24,Scoring!V$3:V$32,0)),"")} | D25: {=IFERROR(INDEX(Scoring!D$3:D$32,MATCH(24,Scoring!V$3:V$32,0)),"")} | E25: {=IFERROR(INDEX(Scoring!E$3:E$32,MATCH(24,Scoring!V$3:V$32,0)),"")} | F25: {=IFERROR(INDEX(Scoring!F$3:F$32,MATCH(24,Scoring!V$3:V$32,0)),"")} | G25: {=IFERROR(INDEX(Scoring!U$3:U$32,MATCH(24,Scoring!V$3:V$32,0)),"")} | H25: {=IFERROR(INDEX(Scoring!T$3:T$32,MATCH(24,Scoring!V$3:V$32,0)),"")}
A26: 25 | B26: {=IFERROR(INDEX(Scoring!B$3:B$32,MATCH(25,Scoring!V$3:V$32,0)),"")} | C26: {=IFERROR(INDEX(Scoring!C$3:C$32,MATCH(25,Scoring!V$3:V$32,0)),"")} | D26: {=IFERROR(INDEX(Scoring!D$3:D$32,MATCH(25,Scoring!V$3:V$32,0)),"")} | E26: {=IFERROR(INDEX(Scoring!E$3:E$32,MATCH(25,Scoring!V$3:V$32,0)),"")} | F26: {=IFERROR(INDEX(Scoring!F$3:F$32,MATCH(25,Scoring!V$3:V$32,0)),"")} | G26: {=IFERROR(INDEX(Scoring!U$3:U$32,MATCH(25,Scoring!V$3:V$32,0)),"")} | H26: {=IFERROR(INDEX(Scoring!T$3:T$32,MATCH(25,Scoring!V$3:V$32,0)),"")}
A27: 26 | B27: {=IFERROR(INDEX(Scoring!B$3:B$32,MATCH(26,Scoring!V$3:V$32,0)),"")} | C27: {=IFERROR(INDEX(Scoring!C$3:C$32,MATCH(26,Scoring!V$3:V$32,0)),"")} | D27: {=IFERROR(INDEX(Scoring!D$3:D$32,MATCH(26,Scoring!V$3:V$32,0)),"")} | E27: {=IFERROR(INDEX(Scoring!E$3:E$32,MATCH(26,Scoring!V$3:V$32,0)),"")} | F27: {=IFERROR(INDEX(Scoring!F$3:F$32,MATCH(26,Scoring!V$3:V$32,0)),"")} | G27: {=IFERROR(INDEX(Scoring!U$3:U$32,MATCH(26,Scoring!V$3:V$32,0)),"")} | H27: {=IFERROR(INDEX(Scoring!T$3:T$32,MATCH(26,Scoring!V$3:V$32,0)),"")}
A28: 27 | B28: {=IFERROR(INDEX(Scoring!B$3:B$32,MATCH(27,Scoring!V$3:V$32,0)),"")} | C28: {=IFERROR(INDEX(Scoring!C$3:C$32,MATCH(27,Scoring!V$3:V$32,0)),"")} | D28: {=IFERROR(INDEX(Scoring!D$3:D$32,MATCH(27,Scoring!V$3:V$32,0)),"")} | E28: {=IFERROR(INDEX(Scoring!E$3:E$32,MATCH(27,Scoring!V$3:V$32,0)),"")} | F28: {=IFERROR(INDEX(Scoring!F$3:F$32,MATCH(27,Scoring!V$3:V$32,0)),"")} | G28: {=IFERROR(INDEX(Scoring!U$3:U$32,MATCH(27,Scoring!V$3:V$32,0)),"")} | H28: {=IFERROR(INDEX(Scoring!T$3:T$32,MATCH(27,Scoring!V$3:V$32,0)),"")}
A29: 28 | B29: {=IFERROR(INDEX(Scoring!B$3:B$32,MATCH(28,Scoring!V$3:V$32,0)),"")} | C29: {=IFERROR(INDEX(Scoring!C$3:C$32,MATCH(28,Scoring!V$3:V$32,0)),"")} | D29: {=IFERROR(INDEX(Scoring!D$3:D$32,MATCH(28,Scoring!V$3:V$32,0)),"")} | E29: {=IFERROR(INDEX(Scoring!E$3:E$32,MATCH(28,Scoring!V$3:V$32,0)),"")} | F29: {=IFERROR(INDEX(Scoring!F$3:F$32,MATCH(28,Scoring!V$3:V$32,0)),"")} | G29: {=IFERROR(INDEX(Scoring!U$3:U$32,MATCH(28,Scoring!V$3:V$32,0)),"")} | H29: {=IFERROR(INDEX(Scoring!T$3:T$32,MATCH(28,Scoring!V$3:V$32,0)),"")}
A30: 29 | B30: {=IFERROR(INDEX(Scoring!B$3:B$32,MATCH(29,Scoring!V$3:V$32,0)),"")} | C30: {=IFERROR(INDEX(Scoring!C$3:C$32,MATCH(29,Scoring!V$3:V$32,0)),"")} | D30: {=IFERROR(INDEX(Scoring!D$3:D$32,MATCH(29,Scoring!V$3:V$32,0)),"")} | E30: {=IFERROR(INDEX(Scoring!E$3:E$32,MATCH(29,Scoring!V$3:V$32,0)),"")} | F30: {=IFERROR(INDEX(Scoring!F$3:F$32,MATCH(29,Scoring!V$3:V$32,0)),"")} | G30: {=IFERROR(INDEX(Scoring!U$3:U$32,MATCH(29,Scoring!V$3:V$32,0)),"")} | H30: {=IFERROR(INDEX(Scoring!T$3:T$32,MATCH(29,Scoring!V$3:V$32,0)),"")}
A31: 30 | B31: {=IFERROR(INDEX(Scoring!B$3:B$32,MATCH(30,Scoring!V$3:V$32,0)),"")} | C31: {=IFERROR(INDEX(Scoring!C$3:C$32,MATCH(30,Scoring!V$3:V$32,0)),"")} | D31: {=IFERROR(INDEX(Scoring!D$3:D$32,MATCH(30,Scoring!V$3:V$32,0)),"")} | E31: {=IFERROR(INDEX(Scoring!E$3:E$32,MATCH(30,Scoring!V$3:V$32,0)),"")} | F31: {=IFERROR(INDEX(Scoring!F$3:F$32,MATCH(30,Scoring!V$3:V$32,0)),"")} | G31: {=IFERROR(INDEX(Scoring!U$3:U$32,MATCH(30,Scoring!V$3:V$32,0)),"")} | H31: {=IFERROR(INDEX(Scoring!T$3:T$32,MATCH(30,Scoring!V$3:V$32,0)),"")}
A34: Disqualified Candidates
B35: {=IFERROR(INDEX(Scoring!B$3:B$32,SMALL(Scoring!AD$3:AD$32,1)),"")} | C35: {=IFERROR(INDEX(Scoring!C$3:C$32,SMALL(Scoring!AD$3:AD$32,1)),"")} | D35: {=IFERROR(INDEX(Scoring!W$3:W$32,SMALL(Scoring!AD$3:AD$32,1)),"")}
B36: {=IFERROR(INDEX(Scoring!B$3:B$32,SMALL(Scoring!AD$3:AD$32,2)),"")} | C36: {=IFERROR(INDEX(Scoring!C$3:C$32,SMALL(Scoring!AD$3:AD$32,2)),"")} | D36: {=IFERROR(INDEX(Scoring!W$3:W$32,SMALL(Scoring!AD$3:AD$32,2)),"")}
B37: {=IFERROR(INDEX(Scoring!B$3:B$32,SMALL(Scoring!AD$3:AD$32,3)),"")} | C37: {=IFERROR(INDEX(Scoring!C$3:C$32,SMALL(Scoring!AD$3:AD$32,3)),"")} | D37: {=IFERROR(INDEX(Scoring!W$3:W$32,SMALL(Scoring!AD$3:AD$32,3)),"")}
B38: {=IFERROR(INDEX(Scoring!B$3:B$32,SMALL(Scoring!AD$3:AD$32,4)),"")} | C38: {=IFERROR(INDEX(Scoring!C$3:C$32,SMALL(Scoring!AD$3:AD$32,4)),"")} | D38: {=IFERROR(INDEX(Scoring!W$3:W$32,SMALL(Scoring!AD$3:AD$32,4)),"")}
B39: {=IFERROR(INDEX(Scoring!B$3:B$32,SMALL(Scoring!AD$3:AD$32,5)),"")} | C39: {=IFERROR(INDEX(Scoring!C$3:C$32,SMALL(Scoring!AD$3:AD$32,5)),"")} | D39: {=IFERROR(INDEX(Scoring!W$3:W$32,SMALL(Scoring!AD$3:AD$32,5)),"")}
B40: {=IFERROR(INDEX(Scoring!B$3:B$32,SMALL(Scoring!AD$3:AD$32,6)),"")} | C40: {=IFERROR(INDEX(Scoring!C$3:C$32,SMALL(Scoring!AD$3:AD$32,6)),"")} | D40: {=IFERROR(INDEX(Scoring!W$3:W$32,SMALL(Scoring!AD$3:AD$32,6)),"")}
B41: {=IFERROR(INDEX(Scoring!B$3:B$32,SMALL(Scoring!AD$3:AD$32,7)),"")} | C41: {=IFERROR(INDEX(Scoring!C$3:C$32,SMALL(Scoring!AD$3:AD$32,7)),"")} | D41: {=IFERROR(INDEX(Scoring!W$3:W$32,SMALL(Scoring!AD$3:AD$32,7)),"")}
B42: {=IFERROR(INDEX(Scoring!B$3:B$32,SMALL(Scoring!AD$3:AD$32,8)),"")} | C42: {=IFERROR(INDEX(Scoring!C$3:C$32,SMALL(Scoring!AD$3:AD$32,8)),"")} | D42: {=IFERROR(INDEX(Scoring!W$3:W$32,SMALL(Scoring!AD$3:AD$32,8)),"")}
...

Sheet Weights
A1: Criterion | B1: Weight (%) | C1: Notes
A2: University Tier | B2: 3 | C2: Low weight — tier influences but doesn't dominate
A3: Department Fit | B3: 3 | C3: Low weight — coursework + projects matter more
A4: GPA | B4: 5 | C4: Mapped from 0–4 scale to 1–5
A5: Academic Recency | B5: 4 | C5: Penalty for long gaps since graduation with no relevant work
A6: Teknofest / Competitions | B6: 6 | C6: None / Once / Multiple or podium
A7: Real Project | B7: 15 | C7: Hands-on UAV/GNC/aero project they actually built or shipped
A8: Portfolio Submitted | B8: 7 | C8: Quality of submitted portfolio/CV/work samples
A9: Relevant Coursework | B9: 6 | C9: Controls, flight mechanics, aerodynamics, estimation
A10: Tools Exposure | B10: 6 | C10: MATLAB/Simulink, Python, ArduPilot, XFLR5, AVL, SITL, ROS
A11: RC/UAV Hands-on | B11: 5 | C11: Has built, flown, or maintained an RC aircraft / quad
A12: English Level | B12: 3 | C12: Reading ArduPilot docs, papers, technical writing
A13: HR Feedback | B13: 7 | C13: Soft skills, team fit, communication, motivation
A14: Tech Interview (composite) | B14: 30 | C14: Average of 5 subscores: Controls, Math, Coding, Debugging, Communication
A15: TOTAL | B15: =SUM(B2:B14)

Sheet Rubric
A1: Criterion | B1: Score 1 (Poor) | C1: Score 2 | D1: Score 3 (Acceptable) | E1: Score 4 | F1: Score 5 (Excellent)
A2: University Tier | B2: Unknown / unranked | C2: Tier D | D2: Tier C | E2: Tier B | F2: Tier A (METU/ITU/Bilkent/Boğaziçi/Koç/Sabancı)
A3: Department Fit | B3: Unrelated (e.g. business) | C3: Distant (CS, IE) | D3: Adjacent (ME, Mechatronics) | E3: Close (EE, Control) | F3: Direct (Aerospace, Aeronautical)
A4: GPA | B4: < 2.0 | C4: 2.0 – 2.49 | D4: 2.5 – 2.99 | E4: 3.0 – 3.49 | F4: ≥ 3.5
A5: Academic Recency | B5: Graduated >3 yrs ago, no relevant work | C5: Graduated 2–3 yrs ago, weak continuity | D5: Graduated 1–2 yrs ago / MSc gap | E5: Fresh grad (≤1 yr) or active MSc | F5: Currently 3rd/4th year or fresh grad with continuity
A6: Teknofest / Competitions | B6: None | C6: Applied but didn't compete | D6: Participated once | E6: Participated multiple times | F6: Multiple participations + podium/finals
A7: Real Project | B7: None / only coursework labs | C7: Small individual project, limited scope | D7: One real team project, basic outcome | E7: Multiple projects, real deliverables | F7: Shipped a working UAV/system, demonstrable results
A8: Portfolio Submitted | B8: Not submitted / very weak | C8: CV only, no work samples | D8: Basic portfolio, some samples | E8: Strong portfolio with code/reports | F8: Excellent — code, reports, videos, results, well-organized
A9: Relevant Coursework | B9: No GNC-adjacent courses | C9: 1 relevant course | D9: 2–3 relevant courses | E9: Most controls/aero/flight mech done | F9: All key courses + advanced electives (estimation, optimal control)
A10: Tools Exposure | B10: None of our stack | C10: Knows MATLAB basics only | D10: MATLAB + Python OR Simulink basics | E10: Solid in MATLAB/Simulink + one domain tool (AVL/XFLR5/ArduPilot) | F10: Multiple tools fluent, has used SITL, log analysis, full pipeline
A11: RC/UAV Hands-on | B11: Never touched an RC platform | C11: Has flown a toy drone | D11: Built a kit, basic soldering | E11: Built custom platform, tuned, flown | F11: Multiple custom builds, autopilot tuning, crash recovery, demonstrable
A12: English Level | B12: Cannot read technical English | C12: Reads with difficulty | D12: Reads docs OK, weak writing | E12: Reads/writes well, OK speaking | F12: Fluent — can write reports, present, read papers fast
... A18: Tech-Communication | B18: Cannot explain their work | C18: Vague, jargon-heavy or missing | D18: Clear on simple things | E18: Explains tradeoffs and reasoning well | F18: Excellent — concise, structured, asks good questions

Sheet Uni_Tiers
A1: University | B1: Tier | C1: Notes | E1: Tier | F1: Score
A2: METU (ODTÜ) | B2: A | C2: Strong aerospace, control, EE | E2: A | F2: 5
A3: ITU | B3: A | C3: Strong aerospace, control | E3: B | F3: 4
A4: Bilkent | B4: A | C4: Strong EE, ME | E4: C | F4: 3
A5: Boğaziçi | B5: A | C5: Strong EE, ME | E5: D | F5: 2
A6: Koç | B6: A | C6: Strong EE, ME | F6: 1
A7: Sabancı | B7: A | C7: Strong EE, mechatronics
A8: Hacettepe | B8: B
A9: Yıldız Teknik | B9: B | C9: Strong ME, control
A10: Gazi | B10: B
A11: TOBB ETÜ | B11: B
A12: Ankara Üniversitesi | B12: B
A13: Ege | B13: B
A14: Erciyes | B14: B | C14: Aerospace program
A15: Eskişehir Osmangazi | B15: B
A16: Eskişehir Teknik (Anadolu) | B16: B | C16: Aerospace program
A17: Atılım | B17: B
A18: İzmir Yüksek Teknoloji (IYTE) | B18: B
A19: Çukurova | B19: C
A20: Selçuk | B20: C
A21: Karadeniz Teknik (KTÜ) | B21: C
A22: Samsun Üniversitesi | B22: C | C22: Aerospace program
A23: THK Üniversitesi | B23: C | C23: Aviation focus
A24: Other | B24: D | C24: Default for unlisted unis

Sheet Dept_Fit
A1: Department | B1: Fit Score | C1: Notes
A2: Aerospace Engineering | B2: 5 | C2: Direct fit
A3: Aeronautical Engineering | B3: 5 | C3: Direct fit
A4: Astronautical Engineering | B4: 5 | C4: Direct fit
A5: Electrical & Electronics Engineering | B5: 4 | C5: Close — controls, embedded, signals
A6: Electronics Engineering | B6: 4
A7: Control Engineering | B7: 4
A8: Mechatronics Engineering | B8: 4
A9: Mechanical Engineering | B9: 3 | C9: Adjacent — depends on electives
A10: Aircraft Maintenance / Airframes | B10: 3
A11: Computer Engineering | B11: 3 | C11: Depends on math + embedded background
A12: Software Engineering | B12: 2 | C12: Distant unless strong math + projects
A13: Industrial Engineering | B13: 2
A14: Physics | B14: 3 | C14: Strong math, may lack engineering tools
A15: Other | B15: 1 | C15: Default — investigate case by case

Sheet Status_Map
A1: Academic Status | B1: Score | C1: Notes
A2: 3rd year | B2: 4 | C2: Junior — still in school, available long-term
A3: 4th year | B3: 5 | C3: Senior — close to graduation, best continuity
A4: Fresh graduate (<1 yr) | B4: 5 | C4: Just graduated, full availability
A5: Graduated 1–2 yrs ago | B5: 4 | C5: Recent grad
A6: Graduated 2–3 yrs ago | B6: 3 | C6: Some gap — check what they did meanwhile
A7: Graduated >3 yrs ago | B7: 2 | C7: Long gap — needs justification
A8: MSc student | B8: 4 | C8: Active in academia, likely strong
